Internal Server Error: /login/
Traceback (most recent call last):
  File "E:\项目\zhigengBlog\venv\lib\site-packages\django\core\handlers\exception.py", line 47, in inner
    response = get_response(request)
  File "E:\项目\zhigengBlog\venv\lib\site-packages\django\core\handlers\base.py", line 179, in _get_response
    response = wrapped_callback(request, *callback_args, **callback_kwargs)
  File "E:\项目\zhigeng_Blog\Login\views.py", line 11, in login
    return render(request, 'login.html')
  File "E:\项目\zhigengBlog\venv\lib\site-packages\django\shortcuts.py", line 19, in render
    content = loader.render_to_string(template_name, context, request, using=using)
  File "E:\项目\zhigengBlog\venv\lib\site-packages\django\template\loader.py", line 62, in render_to_string
    return template.render(context, request)
  File "E:\项目\zhigengBlog\venv\lib\site-packages\django\template\backends\django.py", line 61, in render
    return self.template.render(context)
  File "E:\项目\zhigengBlog\venv\lib\site-packages\django\template\base.py", line 170, in render
    return self._render(context)
  File "E:\项目\zhigengBlog\venv\lib\site-packages\django\template\base.py", line 162, in _render
    return self.nodelist.render(context)
  File "E:\项目\zhigengBlog\venv\lib\site-packages\django\template\base.py", line 938, in render
    bit = node.render_annotated(context)
  File "E:\项目\zhigengBlog\venv\lib\site-packages\django\template\base.py", line 905, in render_annotated
    return self.render(context)
  File "E:\项目\zhigengBlog\venv\lib\site-packages\django\template\defaulttags.py", line 446, in render
    url = reverse(view_name, args=args, kwargs=kwargs, current_app=current_app)
  File "E:\项目\zhigengBlog\venv\lib\site-packages\django\urls\base.py", line 87, in reverse
    return iri_to_uri(resolver._reverse_with_prefix(view, prefix, *args, **kwargs))
  File "E:\项目\zhigengBlog\venv\lib\site-packages\django\urls\resolvers.py", line 685, in _reverse_with_prefix
    raise NoReverseMatch(msg)
django.urls.exceptions.NoReverseMatch: Reverse for 'login' not found. 'login' is not a valid view function or pattern name.
Internal Server Error: /login/
Traceback (most recent call last):
  File "E:\项目\zhigengBlog\venv\lib\site-packages\django\core\handlers\exception.py", line 47, in inner
    response = get_response(request)
  File "E:\项目\zhigengBlog\venv\lib\site-packages\django\core\handlers\base.py", line 179, in _get_response
    response = wrapped_callback(request, *callback_args, **callback_kwargs)
  File "E:\项目\zhigeng_Blog\Login\views.py", line 11, in login
    return render(request, 'templates/login.html')
  File "E:\项目\zhigengBlog\venv\lib\site-packages\django\shortcuts.py", line 19, in render
    content = loader.render_to_string(template_name, context, request, using=using)
  File "E:\项目\zhigengBlog\venv\lib\site-packages\django\template\loader.py", line 61, in render_to_string
    template = get_template(template_name, using=using)
  File "E:\项目\zhigengBlog\venv\lib\site-packages\django\template\loader.py", line 19, in get_template
    raise TemplateDoesNotExist(template_name, chain=chain)
django.template.exceptions.TemplateDoesNotExist: templates/login.html
Internal Server Error: /login/
Traceback (most recent call last):
  File "E:\项目\zhigengBlog\venv\lib\site-packages\django\core\handlers\exception.py", line 47, in inner
    response = get_response(request)
  File "E:\项目\zhigengBlog\venv\lib\site-packages\django\core\handlers\base.py", line 179, in _get_response
    response = wrapped_callback(request, *callback_args, **callback_kwargs)
  File "E:\项目\zhigeng_Blog\Login\views.py", line 11, in login
    return render(request, 'login.html')
  File "E:\项目\zhigengBlog\venv\lib\site-packages\django\shortcuts.py", line 19, in render
    content = loader.render_to_string(template_name, context, request, using=using)
  File "E:\项目\zhigengBlog\venv\lib\site-packages\django\template\loader.py", line 62, in render_to_string
    return template.render(context, request)
  File "E:\项目\zhigengBlog\venv\lib\site-packages\django\template\backends\django.py", line 61, in render
    return self.template.render(context)
  File "E:\项目\zhigengBlog\venv\lib\site-packages\django\template\base.py", line 170, in render
    return self._render(context)
  File "E:\项目\zhigengBlog\venv\lib\site-packages\django\template\base.py", line 162, in _render
    return self.nodelist.render(context)
  File "E:\项目\zhigengBlog\venv\lib\site-packages\django\template\base.py", line 938, in render
    bit = node.render_annotated(context)
  File "E:\项目\zhigengBlog\venv\lib\site-packages\django\template\base.py", line 905, in render_annotated
    return self.render(context)
  File "E:\项目\zhigengBlog\venv\lib\site-packages\django\template\defaulttags.py", line 446, in render
    url = reverse(view_name, args=args, kwargs=kwargs, current_app=current_app)
  File "E:\项目\zhigengBlog\venv\lib\site-packages\django\urls\base.py", line 87, in reverse
    return iri_to_uri(resolver._reverse_with_prefix(view, prefix, *args, **kwargs))
  File "E:\项目\zhigengBlog\venv\lib\site-packages\django\urls\resolvers.py", line 685, in _reverse_with_prefix
    raise NoReverseMatch(msg)
django.urls.exceptions.NoReverseMatch: Reverse for 'login' not found. 'login' is not a valid view function or pattern name.
Internal Server Error: /login/
Traceback (most recent call last):
  File "E:\项目\zhigengBlog\venv\lib\site-packages\django\core\handlers\exception.py", line 47, in inner
    response = get_response(request)
  File "E:\项目\zhigengBlog\venv\lib\site-packages\django\core\handlers\base.py", line 179, in _get_response
    response = wrapped_callback(request, *callback_args, **callback_kwargs)
  File "E:\项目\zhigeng_Blog\Login\views.py", line 11, in login
    return render(request, 'login.html')
  File "E:\项目\zhigengBlog\venv\lib\site-packages\django\shortcuts.py", line 19, in render
    content = loader.render_to_string(template_name, context, request, using=using)
  File "E:\项目\zhigengBlog\venv\lib\site-packages\django\template\loader.py", line 62, in render_to_string
    return template.render(context, request)
  File "E:\项目\zhigengBlog\venv\lib\site-packages\django\template\backends\django.py", line 61, in render
    return self.template.render(context)
  File "E:\项目\zhigengBlog\venv\lib\site-packages\django\template\base.py", line 170, in render
    return self._render(context)
  File "E:\项目\zhigengBlog\venv\lib\site-packages\django\template\base.py", line 162, in _render
    return self.nodelist.render(context)
  File "E:\项目\zhigengBlog\venv\lib\site-packages\django\template\base.py", line 938, in render
    bit = node.render_annotated(context)
  File "E:\项目\zhigengBlog\venv\lib\site-packages\django\template\base.py", line 905, in render_annotated
    return self.render(context)
  File "E:\项目\zhigengBlog\venv\lib\site-packages\django\template\defaulttags.py", line 446, in render
    url = reverse(view_name, args=args, kwargs=kwargs, current_app=current_app)
  File "E:\项目\zhigengBlog\venv\lib\site-packages\django\urls\base.py", line 87, in reverse
    return iri_to_uri(resolver._reverse_with_prefix(view, prefix, *args, **kwargs))
  File "E:\项目\zhigengBlog\venv\lib\site-packages\django\urls\resolvers.py", line 685, in _reverse_with_prefix
    raise NoReverseMatch(msg)
django.urls.exceptions.NoReverseMatch: Reverse for 'login' not found. 'login' is not a valid view function or pattern name.
Internal Server Error: /login/
Traceback (most recent call last):
  File "E:\项目\zhigengBlog\venv\lib\site-packages\django\core\handlers\exception.py", line 47, in inner
    response = get_response(request)
  File "E:\项目\zhigengBlog\venv\lib\site-packages\django\core\handlers\base.py", line 179, in _get_response
    response = wrapped_callback(request, *callback_args, **callback_kwargs)
  File "E:\项目\zhigeng_Blog\Login\views.py", line 11, in login
    return render(request, 'login.html')
  File "E:\项目\zhigengBlog\venv\lib\site-packages\django\shortcuts.py", line 19, in render
    content = loader.render_to_string(template_name, context, request, using=using)
  File "E:\项目\zhigengBlog\venv\lib\site-packages\django\template\loader.py", line 62, in render_to_string
    return template.render(context, request)
  File "E:\项目\zhigengBlog\venv\lib\site-packages\django\template\backends\django.py", line 61, in render
    return self.template.render(context)
  File "E:\项目\zhigengBlog\venv\lib\site-packages\django\template\base.py", line 170, in render
    return self._render(context)
  File "E:\项目\zhigengBlog\venv\lib\site-packages\django\template\base.py", line 162, in _render
    return self.nodelist.render(context)
  File "E:\项目\zhigengBlog\venv\lib\site-packages\django\template\base.py", line 938, in render
    bit = node.render_annotated(context)
  File "E:\项目\zhigengBlog\venv\lib\site-packages\django\template\base.py", line 905, in render_annotated
    return self.render(context)
  File "E:\项目\zhigengBlog\venv\lib\site-packages\django\template\defaulttags.py", line 446, in render
    url = reverse(view_name, args=args, kwargs=kwargs, current_app=current_app)
  File "E:\项目\zhigengBlog\venv\lib\site-packages\django\urls\base.py", line 87, in reverse
    return iri_to_uri(resolver._reverse_with_prefix(view, prefix, *args, **kwargs))
  File "E:\项目\zhigengBlog\venv\lib\site-packages\django\urls\resolvers.py", line 685, in _reverse_with_prefix
    raise NoReverseMatch(msg)
django.urls.exceptions.NoReverseMatch: Reverse for 'login/' not found. 'login/' is not a valid view function or pattern name.
Internal Server Error: /login/
Traceback (most recent call last):
  File "E:\项目\zhigengBlog\venv\lib\site-packages\django\core\handlers\exception.py", line 47, in inner
    response = get_response(request)
  File "E:\项目\zhigengBlog\venv\lib\site-packages\django\core\handlers\base.py", line 179, in _get_response
    response = wrapped_callback(request, *callback_args, **callback_kwargs)
  File "E:\项目\zhigeng_Blog\Login\views.py", line 11, in login
    return render(request, 'login.html')
  File "E:\项目\zhigengBlog\venv\lib\site-packages\django\shortcuts.py", line 19, in render
    content = loader.render_to_string(template_name, context, request, using=using)
  File "E:\项目\zhigengBlog\venv\lib\site-packages\django\template\loader.py", line 62, in render_to_string
    return template.render(context, request)
  File "E:\项目\zhigengBlog\venv\lib\site-packages\django\template\backends\django.py", line 61, in render
    return self.template.render(context)
  File "E:\项目\zhigengBlog\venv\lib\site-packages\django\template\base.py", line 170, in render
    return self._render(context)
  File "E:\项目\zhigengBlog\venv\lib\site-packages\django\template\base.py", line 162, in _render
    return self.nodelist.render(context)
  File "E:\项目\zhigengBlog\venv\lib\site-packages\django\template\base.py", line 938, in render
    bit = node.render_annotated(context)
  File "E:\项目\zhigengBlog\venv\lib\site-packages\django\template\base.py", line 905, in render_annotated
    return self.render(context)
  File "E:\项目\zhigengBlog\venv\lib\site-packages\django\template\defaulttags.py", line 446, in render
    url = reverse(view_name, args=args, kwargs=kwargs, current_app=current_app)
  File "E:\项目\zhigengBlog\venv\lib\site-packages\django\urls\base.py", line 87, in reverse
    return iri_to_uri(resolver._reverse_with_prefix(view, prefix, *args, **kwargs))
  File "E:\项目\zhigengBlog\venv\lib\site-packages\django\urls\resolvers.py", line 685, in _reverse_with_prefix
    raise NoReverseMatch(msg)
django.urls.exceptions.NoReverseMatch: Reverse for 'login/' not found. 'login/' is not a valid view function or pattern name.
Internal Server Error: /login/
Traceback (most recent call last):
  File "C:\Users\22520\AppData\Local\Programs\Python\Python39\lib\site-packages\django\core\handlers\exception.py", line 47, in inner
    response = get_response(request)
  File "C:\Users\22520\AppData\Local\Programs\Python\Python39\lib\site-packages\django\core\handlers\base.py", line 179, in _get_response
    response = wrapped_callback(request, *callback_args, **callback_kwargs)
  File "D:\text1\zhigeng_Blog\Login\views.py", line 11, in login
    return render('index.html')
TypeError: render() missing 1 required positional argument: 'template_name'
Internal Server Error: /login/
Traceback (most recent call last):
  File "C:\Users\22520\AppData\Local\Programs\Python\Python39\lib\site-packages\django\core\handlers\exception.py", line 47, in inner
    response = get_response(request)
  File "C:\Users\22520\AppData\Local\Programs\Python\Python39\lib\site-packages\django\core\handlers\base.py", line 179, in _get_response
    response = wrapped_callback(request, *callback_args, **callback_kwargs)
  File "D:\text1\zhigeng_Blog\Login\views.py", line 11, in login
    return render('index.html')
TypeError: render() missing 1 required positional argument: 'template_name'
Internal Server Error: /index/
Traceback (most recent call last):
  File "C:\Users\22520\AppData\Local\Programs\Python\Python39\lib\site-packages\django\core\handlers\exception.py", line 47, in inner
    response = get_response(request)
  File "C:\Users\22520\AppData\Local\Programs\Python\Python39\lib\site-packages\django\core\handlers\base.py", line 179, in _get_response
    response = wrapped_callback(request, *callback_args, **callback_kwargs)
  File "D:\text1\zhigeng_Blog\Login\views.py", line 6, in index
    return render(request, 'login/index.html')
  File "C:\Users\22520\AppData\Local\Programs\Python\Python39\lib\site-packages\django\shortcuts.py", line 19, in render
    content = loader.render_to_string(template_name, context, request, using=using)
  File "C:\Users\22520\AppData\Local\Programs\Python\Python39\lib\site-packages\django\template\loader.py", line 61, in render_to_string
    template = get_template(template_name, using=using)
  File "C:\Users\22520\AppData\Local\Programs\Python\Python39\lib\site-packages\django\template\loader.py", line 19, in get_template
    raise TemplateDoesNotExist(template_name, chain=chain)
django.template.exceptions.TemplateDoesNotExist: login/index.html
Internal Server Error: /index/
Traceback (most recent call last):
  File "C:\Users\22520\AppData\Local\Programs\Python\Python39\lib\site-packages\django\core\handlers\exception.py", line 47, in inner
    response = get_response(request)
  File "C:\Users\22520\AppData\Local\Programs\Python\Python39\lib\site-packages\django\core\handlers\base.py", line 179, in _get_response
    response = wrapped_callback(request, *callback_args, **callback_kwargs)
  File "D:\text1\zhigeng_Blog\Login\views.py", line 6, in index
    return render(request, 'login/index.html')
  File "C:\Users\22520\AppData\Local\Programs\Python\Python39\lib\site-packages\django\shortcuts.py", line 19, in render
    content = loader.render_to_string(template_name, context, request, using=using)
  File "C:\Users\22520\AppData\Local\Programs\Python\Python39\lib\site-packages\django\template\loader.py", line 61, in render_to_string
    template = get_template(template_name, using=using)
  File "C:\Users\22520\AppData\Local\Programs\Python\Python39\lib\site-packages\django\template\loader.py", line 19, in get_template
    raise TemplateDoesNotExist(template_name, chain=chain)
django.template.exceptions.TemplateDoesNotExist: login/index.html
Internal Server Error: /index/login/
Traceback (most recent call last):
  File "C:\Users\22520\AppData\Local\Programs\Python\Python39\lib\site-packages\django\core\handlers\exception.py", line 47, in inner
    response = get_response(request)
  File "C:\Users\22520\AppData\Local\Programs\Python\Python39\lib\site-packages\django\core\handlers\base.py", line 179, in _get_response
    response = wrapped_callback(request, *callback_args, **callback_kwargs)
  File "D:\text1\zhigeng_Blog\Login\views.py", line 6, in index
    return render(request, 'login/index.html')
  File "C:\Users\22520\AppData\Local\Programs\Python\Python39\lib\site-packages\django\shortcuts.py", line 19, in render
    content = loader.render_to_string(template_name, context, request, using=using)
  File "C:\Users\22520\AppData\Local\Programs\Python\Python39\lib\site-packages\django\template\loader.py", line 61, in render_to_string
    template = get_template(template_name, using=using)
  File "C:\Users\22520\AppData\Local\Programs\Python\Python39\lib\site-packages\django\template\loader.py", line 19, in get_template
    raise TemplateDoesNotExist(template_name, chain=chain)
django.template.exceptions.TemplateDoesNotExist: login/index.html
Internal Server Error: /index/login/
Traceback (most recent call last):
  File "C:\Users\22520\AppData\Local\Programs\Python\Python39\lib\site-packages\django\core\handlers\exception.py", line 47, in inner
    response = get_response(request)
  File "C:\Users\22520\AppData\Local\Programs\Python\Python39\lib\site-packages\django\core\handlers\base.py", line 179, in _get_response
    response = wrapped_callback(request, *callback_args, **callback_kwargs)
  File "D:\text1\zhigeng_Blog\Login\views.py", line 6, in index
    return render(request, 'login/index.html')
  File "C:\Users\22520\AppData\Local\Programs\Python\Python39\lib\site-packages\django\shortcuts.py", line 19, in render
    content = loader.render_to_string(template_name, context, request, using=using)
  File "C:\Users\22520\AppData\Local\Programs\Python\Python39\lib\site-packages\django\template\loader.py", line 61, in render_to_string
    template = get_template(template_name, using=using)
  File "C:\Users\22520\AppData\Local\Programs\Python\Python39\lib\site-packages\django\template\loader.py", line 19, in get_template
    raise TemplateDoesNotExist(template_name, chain=chain)
django.template.exceptions.TemplateDoesNotExist: login/index.html
Internal Server Error: /index/
Traceback (most recent call last):
  File "C:\Users\22520\AppData\Local\Programs\Python\Python39\lib\site-packages\django\core\handlers\exception.py", line 47, in inner
    response = get_response(request)
  File "C:\Users\22520\AppData\Local\Programs\Python\Python39\lib\site-packages\django\core\handlers\base.py", line 179, in _get_response
    response = wrapped_callback(request, *callback_args, **callback_kwargs)
  File "D:\text1\zhigeng_Blog\Login\views.py", line 6, in index
    return render(request, 'login/index.html')
  File "C:\Users\22520\AppData\Local\Programs\Python\Python39\lib\site-packages\django\shortcuts.py", line 19, in render
    content = loader.render_to_string(template_name, context, request, using=using)
  File "C:\Users\22520\AppData\Local\Programs\Python\Python39\lib\site-packages\django\template\loader.py", line 61, in render_to_string
    template = get_template(template_name, using=using)
  File "C:\Users\22520\AppData\Local\Programs\Python\Python39\lib\site-packages\django\template\loader.py", line 19, in get_template
    raise TemplateDoesNotExist(template_name, chain=chain)
django.template.exceptions.TemplateDoesNotExist: login/index.html
Internal Server Error: /login/
Traceback (most recent call last):
  File "C:\Users\22520\AppData\Local\Programs\Python\Python39\lib\site-packages\django\core\handlers\exception.py", line 47, in inner
    response = get_response(request)
  File "C:\Users\22520\AppData\Local\Programs\Python\Python39\lib\site-packages\django\core\handlers\base.py", line 179, in _get_response
    response = wrapped_callback(request, *callback_args, **callback_kwargs)
  File "D:\text1\zhigeng_Blog\Login\views.py", line 11, in login
    return render(request, 'login.html')
  File "C:\Users\22520\AppData\Local\Programs\Python\Python39\lib\site-packages\django\shortcuts.py", line 19, in render
    content = loader.render_to_string(template_name, context, request, using=using)
  File "C:\Users\22520\AppData\Local\Programs\Python\Python39\lib\site-packages\django\template\loader.py", line 62, in render_to_string
    return template.render(context, request)
  File "C:\Users\22520\AppData\Local\Programs\Python\Python39\lib\site-packages\django\template\backends\django.py", line 61, in render
    return self.template.render(context)
  File "C:\Users\22520\AppData\Local\Programs\Python\Python39\lib\site-packages\django\template\base.py", line 170, in render
    return self._render(context)
  File "C:\Users\22520\AppData\Local\Programs\Python\Python39\lib\site-packages\django\template\base.py", line 162, in _render
    return self.nodelist.render(context)
  File "C:\Users\22520\AppData\Local\Programs\Python\Python39\lib\site-packages\django\template\base.py", line 938, in render
    bit = node.render_annotated(context)
  File "C:\Users\22520\AppData\Local\Programs\Python\Python39\lib\site-packages\django\template\base.py", line 905, in render_annotated
    return self.render(context)
  File "C:\Users\22520\AppData\Local\Programs\Python\Python39\lib\site-packages\django\template\defaulttags.py", line 446, in render
    url = reverse(view_name, args=args, kwargs=kwargs, current_app=current_app)
  File "C:\Users\22520\AppData\Local\Programs\Python\Python39\lib\site-packages\django\urls\base.py", line 87, in reverse
    return iri_to_uri(resolver._reverse_with_prefix(view, prefix, *args, **kwargs))
  File "C:\Users\22520\AppData\Local\Programs\Python\Python39\lib\site-packages\django\urls\resolvers.py", line 685, in _reverse_with_prefix
    raise NoReverseMatch(msg)
django.urls.exceptions.NoReverseMatch: Reverse for 'login' not found. 'login' is not a valid view function or pattern name.
Internal Server Error: /index/login/
Traceback (most recent call last):
  File "C:\Users\22520\AppData\Local\Programs\Python\Python39\lib\site-packages\django\core\handlers\exception.py", line 47, in inner
    response = get_response(request)
  File "C:\Users\22520\AppData\Local\Programs\Python\Python39\lib\site-packages\django\core\handlers\base.py", line 179, in _get_response
    response = wrapped_callback(request, *callback_args, **callback_kwargs)
  File "D:\text1\zhigeng_Blog\Login\views.py", line 6, in index
    return render(request, 'login/index.html')
  File "C:\Users\22520\AppData\Local\Programs\Python\Python39\lib\site-packages\django\shortcuts.py", line 19, in render
    content = loader.render_to_string(template_name, context, request, using=using)
  File "C:\Users\22520\AppData\Local\Programs\Python\Python39\lib\site-packages\django\template\loader.py", line 61, in render_to_string
    template = get_template(template_name, using=using)
  File "C:\Users\22520\AppData\Local\Programs\Python\Python39\lib\site-packages\django\template\loader.py", line 19, in get_template
    raise TemplateDoesNotExist(template_name, chain=chain)
django.template.exceptions.TemplateDoesNotExist: login/index.html
Internal Server Error: /index/
Traceback (most recent call last):
  File "C:\Users\22520\AppData\Local\Programs\Python\Python39\lib\site-packages\django\core\handlers\exception.py", line 47, in inner
    response = get_response(request)
  File "C:\Users\22520\AppData\Local\Programs\Python\Python39\lib\site-packages\django\core\handlers\base.py", line 179, in _get_response
    response = wrapped_callback(request, *callback_args, **callback_kwargs)
  File "D:\text1\zhigeng_Blog\Login\views.py", line 6, in index
    return render(request, 'login/index.html')
  File "C:\Users\22520\AppData\Local\Programs\Python\Python39\lib\site-packages\django\shortcuts.py", line 19, in render
    content = loader.render_to_string(template_name, context, request, using=using)
  File "C:\Users\22520\AppData\Local\Programs\Python\Python39\lib\site-packages\django\template\loader.py", line 61, in render_to_string
    template = get_template(template_name, using=using)
  File "C:\Users\22520\AppData\Local\Programs\Python\Python39\lib\site-packages\django\template\loader.py", line 19, in get_template
    raise TemplateDoesNotExist(template_name, chain=chain)
django.template.exceptions.TemplateDoesNotExist: login/index.html
Internal Server Error: /index/
Traceback (most recent call last):
  File "C:\Users\22520\AppData\Local\Programs\Python\Python39\lib\site-packages\django\core\handlers\exception.py", line 47, in inner
    response = get_response(request)
  File "C:\Users\22520\AppData\Local\Programs\Python\Python39\lib\site-packages\django\core\handlers\base.py", line 179, in _get_response
    response = wrapped_callback(request, *callback_args, **callback_kwargs)
  File "D:\text1\zhigeng_Blog\Login\views.py", line 6, in index
    return render(request, 'login/index.html')
  File "C:\Users\22520\AppData\Local\Programs\Python\Python39\lib\site-packages\django\shortcuts.py", line 19, in render
    content = loader.render_to_string(template_name, context, request, using=using)
  File "C:\Users\22520\AppData\Local\Programs\Python\Python39\lib\site-packages\django\template\loader.py", line 61, in render_to_string
    template = get_template(template_name, using=using)
  File "C:\Users\22520\AppData\Local\Programs\Python\Python39\lib\site-packages\django\template\loader.py", line 19, in get_template
    raise TemplateDoesNotExist(template_name, chain=chain)
django.template.exceptions.TemplateDoesNotExist: login/index.html
Internal Server Error: /login/
Traceback (most recent call last):
  File "C:\Users\22520\AppData\Local\Programs\Python\Python39\lib\site-packages\django\core\handlers\exception.py", line 47, in inner
    response = get_response(request)
  File "C:\Users\22520\AppData\Local\Programs\Python\Python39\lib\site-packages\django\core\handlers\base.py", line 179, in _get_response
    response = wrapped_callback(request, *callback_args, **callback_kwargs)
  File "D:\text1\zhigeng_Blog\Login\views.py", line 11, in login
    return render(request, 'login.html')
  File "C:\Users\22520\AppData\Local\Programs\Python\Python39\lib\site-packages\django\shortcuts.py", line 19, in render
    content = loader.render_to_string(template_name, context, request, using=using)
  File "C:\Users\22520\AppData\Local\Programs\Python\Python39\lib\site-packages\django\template\loader.py", line 62, in render_to_string
    return template.render(context, request)
  File "C:\Users\22520\AppData\Local\Programs\Python\Python39\lib\site-packages\django\template\backends\django.py", line 61, in render
    return self.template.render(context)
  File "C:\Users\22520\AppData\Local\Programs\Python\Python39\lib\site-packages\django\template\base.py", line 170, in render
    return self._render(context)
  File "C:\Users\22520\AppData\Local\Programs\Python\Python39\lib\site-packages\django\template\base.py", line 162, in _render
    return self.nodelist.render(context)
  File "C:\Users\22520\AppData\Local\Programs\Python\Python39\lib\site-packages\django\template\base.py", line 938, in render
    bit = node.render_annotated(context)
  File "C:\Users\22520\AppData\Local\Programs\Python\Python39\lib\site-packages\django\template\base.py", line 905, in render_annotated
    return self.render(context)
  File "C:\Users\22520\AppData\Local\Programs\Python\Python39\lib\site-packages\django\template\defaulttags.py", line 446, in render
    url = reverse(view_name, args=args, kwargs=kwargs, current_app=current_app)
  File "C:\Users\22520\AppData\Local\Programs\Python\Python39\lib\site-packages\django\urls\base.py", line 87, in reverse
    return iri_to_uri(resolver._reverse_with_prefix(view, prefix, *args, **kwargs))
  File "C:\Users\22520\AppData\Local\Programs\Python\Python39\lib\site-packages\django\urls\resolvers.py", line 685, in _reverse_with_prefix
    raise NoReverseMatch(msg)
django.urls.exceptions.NoReverseMatch: Reverse for 'login' not found. 'login' is not a valid view function or pattern name.
Internal Server Error: /login/
Traceback (most recent call last):
  File "C:\Users\22520\AppData\Local\Programs\Python\Python39\lib\site-packages\django\core\handlers\exception.py", line 47, in inner
    response = get_response(request)
  File "C:\Users\22520\AppData\Local\Programs\Python\Python39\lib\site-packages\django\core\handlers\base.py", line 179, in _get_response
    response = wrapped_callback(request, *callback_args, **callback_kwargs)
  File "D:\text1\zhigeng_Blog\Login\views.py", line 11, in login
    return render(request, 'login.html')
  File "C:\Users\22520\AppData\Local\Programs\Python\Python39\lib\site-packages\django\shortcuts.py", line 19, in render
    content = loader.render_to_string(template_name, context, request, using=using)
  File "C:\Users\22520\AppData\Local\Programs\Python\Python39\lib\site-packages\django\template\loader.py", line 62, in render_to_string
    return template.render(context, request)
  File "C:\Users\22520\AppData\Local\Programs\Python\Python39\lib\site-packages\django\template\backends\django.py", line 61, in render
    return self.template.render(context)
  File "C:\Users\22520\AppData\Local\Programs\Python\Python39\lib\site-packages\django\template\base.py", line 170, in render
    return self._render(context)
  File "C:\Users\22520\AppData\Local\Programs\Python\Python39\lib\site-packages\django\template\base.py", line 162, in _render
    return self.nodelist.render(context)
  File "C:\Users\22520\AppData\Local\Programs\Python\Python39\lib\site-packages\django\template\base.py", line 938, in render
    bit = node.render_annotated(context)
  File "C:\Users\22520\AppData\Local\Programs\Python\Python39\lib\site-packages\django\template\base.py", line 905, in render_annotated
    return self.render(context)
  File "C:\Users\22520\AppData\Local\Programs\Python\Python39\lib\site-packages\django\template\defaulttags.py", line 446, in render
    url = reverse(view_name, args=args, kwargs=kwargs, current_app=current_app)
  File "C:\Users\22520\AppData\Local\Programs\Python\Python39\lib\site-packages\django\urls\base.py", line 87, in reverse
    return iri_to_uri(resolver._reverse_with_prefix(view, prefix, *args, **kwargs))
  File "C:\Users\22520\AppData\Local\Programs\Python\Python39\lib\site-packages\django\urls\resolvers.py", line 685, in _reverse_with_prefix
    raise NoReverseMatch(msg)
django.urls.exceptions.NoReverseMatch: Reverse for 'login' not found. 'login' is not a valid view function or pattern name.
Internal Server Error: /login/
Traceback (most recent call last):
  File "C:\Users\22520\AppData\Local\Programs\Python\Python39\lib\site-packages\django\core\handlers\exception.py", line 47, in inner
    response = get_response(request)
  File "C:\Users\22520\AppData\Local\Programs\Python\Python39\lib\site-packages\django\core\handlers\base.py", line 179, in _get_response
    response = wrapped_callback(request, *callback_args, **callback_kwargs)
  File "D:\text1\zhigeng_Blog\Login\views.py", line 11, in login
    return render(request, 'login.html')
  File "C:\Users\22520\AppData\Local\Programs\Python\Python39\lib\site-packages\django\shortcuts.py", line 19, in render
    content = loader.render_to_string(template_name, context, request, using=using)
  File "C:\Users\22520\AppData\Local\Programs\Python\Python39\lib\site-packages\django\template\loader.py", line 62, in render_to_string
    return template.render(context, request)
  File "C:\Users\22520\AppData\Local\Programs\Python\Python39\lib\site-packages\django\template\backends\django.py", line 61, in render
    return self.template.render(context)
  File "C:\Users\22520\AppData\Local\Programs\Python\Python39\lib\site-packages\django\template\base.py", line 170, in render
    return self._render(context)
  File "C:\Users\22520\AppData\Local\Programs\Python\Python39\lib\site-packages\django\template\base.py", line 162, in _render
    return self.nodelist.render(context)
  File "C:\Users\22520\AppData\Local\Programs\Python\Python39\lib\site-packages\django\template\base.py", line 938, in render
    bit = node.render_annotated(context)
  File "C:\Users\22520\AppData\Local\Programs\Python\Python39\lib\site-packages\django\template\base.py", line 905, in render_annotated
    return self.render(context)
  File "C:\Users\22520\AppData\Local\Programs\Python\Python39\lib\site-packages\django\template\defaulttags.py", line 446, in render
    url = reverse(view_name, args=args, kwargs=kwargs, current_app=current_app)
  File "C:\Users\22520\AppData\Local\Programs\Python\Python39\lib\site-packages\django\urls\base.py", line 87, in reverse
    return iri_to_uri(resolver._reverse_with_prefix(view, prefix, *args, **kwargs))
  File "C:\Users\22520\AppData\Local\Programs\Python\Python39\lib\site-packages\django\urls\resolvers.py", line 685, in _reverse_with_prefix
    raise NoReverseMatch(msg)
django.urls.exceptions.NoReverseMatch: Reverse for 'login' not found. 'login' is not a valid view function or pattern name.
Internal Server Error: /login/
Traceback (most recent call last):
  File "C:\Users\22520\AppData\Local\Programs\Python\Python39\lib\site-packages\django\core\handlers\exception.py", line 47, in inner
    response = get_response(request)
  File "C:\Users\22520\AppData\Local\Programs\Python\Python39\lib\site-packages\django\core\handlers\base.py", line 179, in _get_response
    response = wrapped_callback(request, *callback_args, **callback_kwargs)
  File "D:\text1\zhigeng_Blog\Login\views.py", line 44, in login
    return render(request, 'login/login.html')
  File "C:\Users\22520\AppData\Local\Programs\Python\Python39\lib\site-packages\django\shortcuts.py", line 19, in render
    content = loader.render_to_string(template_name, context, request, using=using)
  File "C:\Users\22520\AppData\Local\Programs\Python\Python39\lib\site-packages\django\template\loader.py", line 61, in render_to_string
    template = get_template(template_name, using=using)
  File "C:\Users\22520\AppData\Local\Programs\Python\Python39\lib\site-packages\django\template\loader.py", line 19, in get_template
    raise TemplateDoesNotExist(template_name, chain=chain)
django.template.exceptions.TemplateDoesNotExist: login/login.html
Internal Server Error: /login/login.html
Traceback (most recent call last):
  File "C:\Users\22520\AppData\Local\Programs\Python\Python39\lib\site-packages\django\core\handlers\exception.py", line 47, in inner
    response = get_response(request)
  File "C:\Users\22520\AppData\Local\Programs\Python\Python39\lib\site-packages\django\core\handlers\base.py", line 179, in _get_response
    response = wrapped_callback(request, *callback_args, **callback_kwargs)
  File "D:\text1\zhigeng_Blog\Login\views.py", line 44, in login
    return render(request, 'login/login.html')
  File "C:\Users\22520\AppData\Local\Programs\Python\Python39\lib\site-packages\django\shortcuts.py", line 19, in render
    content = loader.render_to_string(template_name, context, request, using=using)
  File "C:\Users\22520\AppData\Local\Programs\Python\Python39\lib\site-packages\django\template\loader.py", line 61, in render_to_string
    template = get_template(template_name, using=using)
  File "C:\Users\22520\AppData\Local\Programs\Python\Python39\lib\site-packages\django\template\loader.py", line 19, in get_template
    raise TemplateDoesNotExist(template_name, chain=chain)
django.template.exceptions.TemplateDoesNotExist: login/login.html
Internal Server Error: /login/login.html
Traceback (most recent call last):
  File "C:\Users\22520\AppData\Local\Programs\Python\Python39\lib\site-packages\django\core\handlers\exception.py", line 47, in inner
    response = get_response(request)
  File "C:\Users\22520\AppData\Local\Programs\Python\Python39\lib\site-packages\django\core\handlers\base.py", line 179, in _get_response
    response = wrapped_callback(request, *callback_args, **callback_kwargs)
  File "D:\text1\zhigeng_Blog\Login\views.py", line 44, in login
    return render(request, 'login/login.html')
  File "C:\Users\22520\AppData\Local\Programs\Python\Python39\lib\site-packages\django\shortcuts.py", line 19, in render
    content = loader.render_to_string(template_name, context, request, using=using)
  File "C:\Users\22520\AppData\Local\Programs\Python\Python39\lib\site-packages\django\template\loader.py", line 61, in render_to_string
    template = get_template(template_name, using=using)
  File "C:\Users\22520\AppData\Local\Programs\Python\Python39\lib\site-packages\django\template\loader.py", line 19, in get_template
    raise TemplateDoesNotExist(template_name, chain=chain)
django.template.exceptions.TemplateDoesNotExist: login/login.html
Internal Server Error: /login/login.html
Traceback (most recent call last):
  File "C:\Users\22520\AppData\Local\Programs\Python\Python39\lib\site-packages\django\core\handlers\exception.py", line 47, in inner
    response = get_response(request)
  File "C:\Users\22520\AppData\Local\Programs\Python\Python39\lib\site-packages\django\core\handlers\base.py", line 179, in _get_response
    response = wrapped_callback(request, *callback_args, **callback_kwargs)
  File "D:\text1\zhigeng_Blog\Login\views.py", line 44, in login
    return render(request, 'login/login.html')
  File "C:\Users\22520\AppData\Local\Programs\Python\Python39\lib\site-packages\django\shortcuts.py", line 19, in render
    content = loader.render_to_string(template_name, context, request, using=using)
  File "C:\Users\22520\AppData\Local\Programs\Python\Python39\lib\site-packages\django\template\loader.py", line 61, in render_to_string
    template = get_template(template_name, using=using)
  File "C:\Users\22520\AppData\Local\Programs\Python\Python39\lib\site-packages\django\template\loader.py", line 19, in get_template
    raise TemplateDoesNotExist(template_name, chain=chain)
django.template.exceptions.TemplateDoesNotExist: login/login.html
Internal Server Error: /login/
Traceback (most recent call last):
  File "C:\Users\22520\AppData\Local\Programs\Python\Python39\lib\site-packages\django\core\handlers\exception.py", line 47, in inner
    response = get_response(request)
  File "C:\Users\22520\AppData\Local\Programs\Python\Python39\lib\site-packages\django\core\handlers\base.py", line 179, in _get_response
    response = wrapped_callback(request, *callback_args, **callback_kwargs)
  File "D:\text1\zhigeng_Blog\Login\views.py", line 44, in login
    return render(request, 'login/login.html')
  File "C:\Users\22520\AppData\Local\Programs\Python\Python39\lib\site-packages\django\shortcuts.py", line 19, in render
    content = loader.render_to_string(template_name, context, request, using=using)
  File "C:\Users\22520\AppData\Local\Programs\Python\Python39\lib\site-packages\django\template\loader.py", line 61, in render_to_string
    template = get_template(template_name, using=using)
  File "C:\Users\22520\AppData\Local\Programs\Python\Python39\lib\site-packages\django\template\loader.py", line 19, in get_template
    raise TemplateDoesNotExist(template_name, chain=chain)
django.template.exceptions.TemplateDoesNotExist: login/login.html
Internal Server Error: /login/
Traceback (most recent call last):
  File "C:\Users\22520\AppData\Local\Programs\Python\Python39\lib\site-packages\django\core\handlers\exception.py", line 47, in inner
    response = get_response(request)
  File "C:\Users\22520\AppData\Local\Programs\Python\Python39\lib\site-packages\django\core\handlers\base.py", line 179, in _get_response
    response = wrapped_callback(request, *callback_args, **callback_kwargs)
  File "D:\text1\zhigeng_Blog\Login\views.py", line 36, in login
    return render(request, 'login.html')
  File "C:\Users\22520\AppData\Local\Programs\Python\Python39\lib\site-packages\django\shortcuts.py", line 19, in render
    content = loader.render_to_string(template_name, context, request, using=using)
  File "C:\Users\22520\AppData\Local\Programs\Python\Python39\lib\site-packages\django\template\loader.py", line 62, in render_to_string
    return template.render(context, request)
  File "C:\Users\22520\AppData\Local\Programs\Python\Python39\lib\site-packages\django\template\backends\django.py", line 61, in render
    return self.template.render(context)
  File "C:\Users\22520\AppData\Local\Programs\Python\Python39\lib\site-packages\django\template\base.py", line 170, in render
    return self._render(context)
  File "C:\Users\22520\AppData\Local\Programs\Python\Python39\lib\site-packages\django\template\base.py", line 162, in _render
    return self.nodelist.render(context)
  File "C:\Users\22520\AppData\Local\Programs\Python\Python39\lib\site-packages\django\template\base.py", line 938, in render
    bit = node.render_annotated(context)
  File "C:\Users\22520\AppData\Local\Programs\Python\Python39\lib\site-packages\django\template\base.py", line 905, in render_annotated
    return self.render(context)
  File "C:\Users\22520\AppData\Local\Programs\Python\Python39\lib\site-packages\django\template\defaulttags.py", line 446, in render
    url = reverse(view_name, args=args, kwargs=kwargs, current_app=current_app)
  File "C:\Users\22520\AppData\Local\Programs\Python\Python39\lib\site-packages\django\urls\base.py", line 87, in reverse
    return iri_to_uri(resolver._reverse_with_prefix(view, prefix, *args, **kwargs))
  File "C:\Users\22520\AppData\Local\Programs\Python\Python39\lib\site-packages\django\urls\resolvers.py", line 685, in _reverse_with_prefix
    raise NoReverseMatch(msg)
django.urls.exceptions.NoReverseMatch: Reverse for 'login' not found. 'login' is not a valid view function or pattern name.
Internal Server Error: /login/
Traceback (most recent call last):
  File "C:\Users\22520\AppData\Local\Programs\Python\Python39\lib\site-packages\django\core\handlers\exception.py", line 47, in inner
    response = get_response(request)
  File "C:\Users\22520\AppData\Local\Programs\Python\Python39\lib\site-packages\django\core\handlers\base.py", line 179, in _get_response
    response = wrapped_callback(request, *callback_args, **callback_kwargs)
  File "D:\text1\zhigeng_Blog\Login\views.py", line 36, in login
    return render(request, 'login.html')
  File "C:\Users\22520\AppData\Local\Programs\Python\Python39\lib\site-packages\django\shortcuts.py", line 19, in render
    content = loader.render_to_string(template_name, context, request, using=using)
  File "C:\Users\22520\AppData\Local\Programs\Python\Python39\lib\site-packages\django\template\loader.py", line 62, in render_to_string
    return template.render(context, request)
  File "C:\Users\22520\AppData\Local\Programs\Python\Python39\lib\site-packages\django\template\backends\django.py", line 61, in render
    return self.template.render(context)
  File "C:\Users\22520\AppData\Local\Programs\Python\Python39\lib\site-packages\django\template\base.py", line 170, in render
    return self._render(context)
  File "C:\Users\22520\AppData\Local\Programs\Python\Python39\lib\site-packages\django\template\base.py", line 162, in _render
    return self.nodelist.render(context)
  File "C:\Users\22520\AppData\Local\Programs\Python\Python39\lib\site-packages\django\template\base.py", line 938, in render
    bit = node.render_annotated(context)
  File "C:\Users\22520\AppData\Local\Programs\Python\Python39\lib\site-packages\django\template\base.py", line 905, in render_annotated
    return self.render(context)
  File "C:\Users\22520\AppData\Local\Programs\Python\Python39\lib\site-packages\django\template\defaulttags.py", line 446, in render
    url = reverse(view_name, args=args, kwargs=kwargs, current_app=current_app)
  File "C:\Users\22520\AppData\Local\Programs\Python\Python39\lib\site-packages\django\urls\base.py", line 87, in reverse
    return iri_to_uri(resolver._reverse_with_prefix(view, prefix, *args, **kwargs))
  File "C:\Users\22520\AppData\Local\Programs\Python\Python39\lib\site-packages\django\urls\resolvers.py", line 685, in _reverse_with_prefix
    raise NoReverseMatch(msg)
django.urls.exceptions.NoReverseMatch: Reverse for 'login' not found. 'login' is not a valid view function or pattern name.
Internal Server Error: /login/
Traceback (most recent call last):
  File "C:\Users\22520\AppData\Local\Programs\Python\Python39\lib\site-packages\django\core\handlers\exception.py", line 47, in inner
    response = get_response(request)
  File "C:\Users\22520\AppData\Local\Programs\Python\Python39\lib\site-packages\django\core\handlers\base.py", line 179, in _get_response
    response = wrapped_callback(request, *callback_args, **callback_kwargs)
  File "D:\text1\zhigeng_Blog\Login\views.py", line 36, in login
    return render(request, 'login.html')
  File "C:\Users\22520\AppData\Local\Programs\Python\Python39\lib\site-packages\django\shortcuts.py", line 19, in render
    content = loader.render_to_string(template_name, context, request, using=using)
  File "C:\Users\22520\AppData\Local\Programs\Python\Python39\lib\site-packages\django\template\loader.py", line 62, in render_to_string
    return template.render(context, request)
  File "C:\Users\22520\AppData\Local\Programs\Python\Python39\lib\site-packages\django\template\backends\django.py", line 61, in render
    return self.template.render(context)
  File "C:\Users\22520\AppData\Local\Programs\Python\Python39\lib\site-packages\django\template\base.py", line 170, in render
    return self._render(context)
  File "C:\Users\22520\AppData\Local\Programs\Python\Python39\lib\site-packages\django\template\base.py", line 162, in _render
    return self.nodelist.render(context)
  File "C:\Users\22520\AppData\Local\Programs\Python\Python39\lib\site-packages\django\template\base.py", line 938, in render
    bit = node.render_annotated(context)
  File "C:\Users\22520\AppData\Local\Programs\Python\Python39\lib\site-packages\django\template\base.py", line 905, in render_annotated
    return self.render(context)
  File "C:\Users\22520\AppData\Local\Programs\Python\Python39\lib\site-packages\django\template\defaulttags.py", line 446, in render
    url = reverse(view_name, args=args, kwargs=kwargs, current_app=current_app)
  File "C:\Users\22520\AppData\Local\Programs\Python\Python39\lib\site-packages\django\urls\base.py", line 87, in reverse
    return iri_to_uri(resolver._reverse_with_prefix(view, prefix, *args, **kwargs))
  File "C:\Users\22520\AppData\Local\Programs\Python\Python39\lib\site-packages\django\urls\resolvers.py", line 685, in _reverse_with_prefix
    raise NoReverseMatch(msg)
django.urls.exceptions.NoReverseMatch: Reverse for 'login' not found. 'login' is not a valid view function or pattern name.
Internal Server Error: /login/
Traceback (most recent call last):
  File "C:\Users\22520\AppData\Local\Programs\Python\Python39\lib\site-packages\django\core\handlers\exception.py", line 47, in inner
    response = get_response(request)
  File "C:\Users\22520\AppData\Local\Programs\Python\Python39\lib\site-packages\django\core\handlers\base.py", line 179, in _get_response
    response = wrapped_callback(request, *callback_args, **callback_kwargs)
  File "D:\text1\zhigeng_Blog\Login\views.py", line 36, in login
    return render(request, 'login.html')
  File "C:\Users\22520\AppData\Local\Programs\Python\Python39\lib\site-packages\django\shortcuts.py", line 19, in render
    content = loader.render_to_string(template_name, context, request, using=using)
  File "C:\Users\22520\AppData\Local\Programs\Python\Python39\lib\site-packages\django\template\loader.py", line 62, in render_to_string
    return template.render(context, request)
  File "C:\Users\22520\AppData\Local\Programs\Python\Python39\lib\site-packages\django\template\backends\django.py", line 61, in render
    return self.template.render(context)
  File "C:\Users\22520\AppData\Local\Programs\Python\Python39\lib\site-packages\django\template\base.py", line 170, in render
    return self._render(context)
  File "C:\Users\22520\AppData\Local\Programs\Python\Python39\lib\site-packages\django\template\base.py", line 162, in _render
    return self.nodelist.render(context)
  File "C:\Users\22520\AppData\Local\Programs\Python\Python39\lib\site-packages\django\template\base.py", line 938, in render
    bit = node.render_annotated(context)
  File "C:\Users\22520\AppData\Local\Programs\Python\Python39\lib\site-packages\django\template\base.py", line 905, in render_annotated
    return self.render(context)
  File "C:\Users\22520\AppData\Local\Programs\Python\Python39\lib\site-packages\django\template\defaulttags.py", line 446, in render
    url = reverse(view_name, args=args, kwargs=kwargs, current_app=current_app)
  File "C:\Users\22520\AppData\Local\Programs\Python\Python39\lib\site-packages\django\urls\base.py", line 87, in reverse
    return iri_to_uri(resolver._reverse_with_prefix(view, prefix, *args, **kwargs))
  File "C:\Users\22520\AppData\Local\Programs\Python\Python39\lib\site-packages\django\urls\resolvers.py", line 685, in _reverse_with_prefix
    raise NoReverseMatch(msg)
django.urls.exceptions.NoReverseMatch: Reverse for 'login' not found. 'login' is not a valid view function or pattern name.
Internal Server Error: /login/
Traceback (most recent call last):
  File "C:\Users\22520\AppData\Local\Programs\Python\Python39\lib\site-packages\django\core\handlers\exception.py", line 47, in inner
    response = get_response(request)
  File "C:\Users\22520\AppData\Local\Programs\Python\Python39\lib\site-packages\django\core\handlers\base.py", line 179, in _get_response
    response = wrapped_callback(request, *callback_args, **callback_kwargs)
  File "D:\text1\zhigeng_Blog\Login\views.py", line 36, in login
    return render(request, 'login.html')
  File "C:\Users\22520\AppData\Local\Programs\Python\Python39\lib\site-packages\django\shortcuts.py", line 19, in render
    content = loader.render_to_string(template_name, context, request, using=using)
  File "C:\Users\22520\AppData\Local\Programs\Python\Python39\lib\site-packages\django\template\loader.py", line 62, in render_to_string
    return template.render(context, request)
  File "C:\Users\22520\AppData\Local\Programs\Python\Python39\lib\site-packages\django\template\backends\django.py", line 61, in render
    return self.template.render(context)
  File "C:\Users\22520\AppData\Local\Programs\Python\Python39\lib\site-packages\django\template\base.py", line 170, in render
    return self._render(context)
  File "C:\Users\22520\AppData\Local\Programs\Python\Python39\lib\site-packages\django\template\base.py", line 162, in _render
    return self.nodelist.render(context)
  File "C:\Users\22520\AppData\Local\Programs\Python\Python39\lib\site-packages\django\template\base.py", line 938, in render
    bit = node.render_annotated(context)
  File "C:\Users\22520\AppData\Local\Programs\Python\Python39\lib\site-packages\django\template\base.py", line 905, in render_annotated
    return self.render(context)
  File "C:\Users\22520\AppData\Local\Programs\Python\Python39\lib\site-packages\django\template\defaulttags.py", line 446, in render
    url = reverse(view_name, args=args, kwargs=kwargs, current_app=current_app)
  File "C:\Users\22520\AppData\Local\Programs\Python\Python39\lib\site-packages\django\urls\base.py", line 87, in reverse
    return iri_to_uri(resolver._reverse_with_prefix(view, prefix, *args, **kwargs))
  File "C:\Users\22520\AppData\Local\Programs\Python\Python39\lib\site-packages\django\urls\resolvers.py", line 685, in _reverse_with_prefix
    raise NoReverseMatch(msg)
django.urls.exceptions.NoReverseMatch: Reverse for 'login' not found. 'login' is not a valid view function or pattern name.
Internal Server Error: /login/
Traceback (most recent call last):
  File "C:\Users\22520\AppData\Local\Programs\Python\Python39\lib\site-packages\django\core\handlers\exception.py", line 47, in inner
    response = get_response(request)
  File "C:\Users\22520\AppData\Local\Programs\Python\Python39\lib\site-packages\django\core\handlers\base.py", line 179, in _get_response
    response = wrapped_callback(request, *callback_args, **callback_kwargs)
  File "D:\text1\zhigeng_Blog\Login\views.py", line 36, in login
    return render(request, 'Login.html')
  File "C:\Users\22520\AppData\Local\Programs\Python\Python39\lib\site-packages\django\shortcuts.py", line 19, in render
    content = loader.render_to_string(template_name, context, request, using=using)
  File "C:\Users\22520\AppData\Local\Programs\Python\Python39\lib\site-packages\django\template\loader.py", line 62, in render_to_string
    return template.render(context, request)
  File "C:\Users\22520\AppData\Local\Programs\Python\Python39\lib\site-packages\django\template\backends\django.py", line 61, in render
    return self.template.render(context)
  File "C:\Users\22520\AppData\Local\Programs\Python\Python39\lib\site-packages\django\template\base.py", line 170, in render
    return self._render(context)
  File "C:\Users\22520\AppData\Local\Programs\Python\Python39\lib\site-packages\django\template\base.py", line 162, in _render
    return self.nodelist.render(context)
  File "C:\Users\22520\AppData\Local\Programs\Python\Python39\lib\site-packages\django\template\base.py", line 938, in render
    bit = node.render_annotated(context)
  File "C:\Users\22520\AppData\Local\Programs\Python\Python39\lib\site-packages\django\template\base.py", line 905, in render_annotated
    return self.render(context)
  File "C:\Users\22520\AppData\Local\Programs\Python\Python39\lib\site-packages\django\template\defaulttags.py", line 446, in render
    url = reverse(view_name, args=args, kwargs=kwargs, current_app=current_app)
  File "C:\Users\22520\AppData\Local\Programs\Python\Python39\lib\site-packages\django\urls\base.py", line 87, in reverse
    return iri_to_uri(resolver._reverse_with_prefix(view, prefix, *args, **kwargs))
  File "C:\Users\22520\AppData\Local\Programs\Python\Python39\lib\site-packages\django\urls\resolvers.py", line 685, in _reverse_with_prefix
    raise NoReverseMatch(msg)
django.urls.exceptions.NoReverseMatch: Reverse for 'login' not found. 'login' is not a valid view function or pattern name.
Internal Server Error: /login/
Traceback (most recent call last):
  File "C:\Users\22520\AppData\Local\Programs\Python\Python39\lib\site-packages\django\core\handlers\exception.py", line 47, in inner
    response = get_response(request)
  File "C:\Users\22520\AppData\Local\Programs\Python\Python39\lib\site-packages\django\core\handlers\base.py", line 179, in _get_response
    response = wrapped_callback(request, *callback_args, **callback_kwargs)
  File "D:\text1\zhigeng_Blog\Login\views.py", line 36, in login
    return render(request, 'Login.html')
  File "C:\Users\22520\AppData\Local\Programs\Python\Python39\lib\site-packages\django\shortcuts.py", line 19, in render
    content = loader.render_to_string(template_name, context, request, using=using)
  File "C:\Users\22520\AppData\Local\Programs\Python\Python39\lib\site-packages\django\template\loader.py", line 62, in render_to_string
    return template.render(context, request)
  File "C:\Users\22520\AppData\Local\Programs\Python\Python39\lib\site-packages\django\template\backends\django.py", line 61, in render
    return self.template.render(context)
  File "C:\Users\22520\AppData\Local\Programs\Python\Python39\lib\site-packages\django\template\base.py", line 170, in render
    return self._render(context)
  File "C:\Users\22520\AppData\Local\Programs\Python\Python39\lib\site-packages\django\template\base.py", line 162, in _render
    return self.nodelist.render(context)
  File "C:\Users\22520\AppData\Local\Programs\Python\Python39\lib\site-packages\django\template\base.py", line 938, in render
    bit = node.render_annotated(context)
  File "C:\Users\22520\AppData\Local\Programs\Python\Python39\lib\site-packages\django\template\base.py", line 905, in render_annotated
    return self.render(context)
  File "C:\Users\22520\AppData\Local\Programs\Python\Python39\lib\site-packages\django\template\defaulttags.py", line 446, in render
    url = reverse(view_name, args=args, kwargs=kwargs, current_app=current_app)
  File "C:\Users\22520\AppData\Local\Programs\Python\Python39\lib\site-packages\django\urls\base.py", line 87, in reverse
    return iri_to_uri(resolver._reverse_with_prefix(view, prefix, *args, **kwargs))
  File "C:\Users\22520\AppData\Local\Programs\Python\Python39\lib\site-packages\django\urls\resolvers.py", line 685, in _reverse_with_prefix
    raise NoReverseMatch(msg)
django.urls.exceptions.NoReverseMatch: Reverse for 'login' not found. 'login' is not a valid view function or pattern name.
Internal Server Error: /login/
Traceback (most recent call last):
  File "C:\Users\22520\AppData\Local\Programs\Python\Python39\lib\site-packages\django\core\handlers\exception.py", line 47, in inner
    response = get_response(request)
  File "C:\Users\22520\AppData\Local\Programs\Python\Python39\lib\site-packages\django\core\handlers\base.py", line 179, in _get_response
    response = wrapped_callback(request, *callback_args, **callback_kwargs)
  File "D:\text1\zhigeng_Blog\Login\views.py", line 36, in login
    return render(request, 'Login.html')
  File "C:\Users\22520\AppData\Local\Programs\Python\Python39\lib\site-packages\django\shortcuts.py", line 19, in render
    content = loader.render_to_string(template_name, context, request, using=using)
  File "C:\Users\22520\AppData\Local\Programs\Python\Python39\lib\site-packages\django\template\loader.py", line 62, in render_to_string
    return template.render(context, request)
  File "C:\Users\22520\AppData\Local\Programs\Python\Python39\lib\site-packages\django\template\backends\django.py", line 61, in render
    return self.template.render(context)
  File "C:\Users\22520\AppData\Local\Programs\Python\Python39\lib\site-packages\django\template\base.py", line 170, in render
    return self._render(context)
  File "C:\Users\22520\AppData\Local\Programs\Python\Python39\lib\site-packages\django\template\base.py", line 162, in _render
    return self.nodelist.render(context)
  File "C:\Users\22520\AppData\Local\Programs\Python\Python39\lib\site-packages\django\template\base.py", line 938, in render
    bit = node.render_annotated(context)
  File "C:\Users\22520\AppData\Local\Programs\Python\Python39\lib\site-packages\django\template\base.py", line 905, in render_annotated
    return self.render(context)
  File "C:\Users\22520\AppData\Local\Programs\Python\Python39\lib\site-packages\django\template\defaulttags.py", line 446, in render
    url = reverse(view_name, args=args, kwargs=kwargs, current_app=current_app)
  File "C:\Users\22520\AppData\Local\Programs\Python\Python39\lib\site-packages\django\urls\base.py", line 87, in reverse
    return iri_to_uri(resolver._reverse_with_prefix(view, prefix, *args, **kwargs))
  File "C:\Users\22520\AppData\Local\Programs\Python\Python39\lib\site-packages\django\urls\resolvers.py", line 685, in _reverse_with_prefix
    raise NoReverseMatch(msg)
django.urls.exceptions.NoReverseMatch: Reverse for 'login' not found. 'login' is not a valid view function or pattern name.
Internal Server Error: /login/
Traceback (most recent call last):
  File "C:\Users\22520\AppData\Local\Programs\Python\Python39\lib\site-packages\django\core\handlers\exception.py", line 47, in inner
    response = get_response(request)
  File "C:\Users\22520\AppData\Local\Programs\Python\Python39\lib\site-packages\django\core\handlers\base.py", line 179, in _get_response
    response = wrapped_callback(request, *callback_args, **callback_kwargs)
  File "D:\text1\zhigeng_Blog\Login\views.py", line 36, in login
    return render(request, 'Login.html')
  File "C:\Users\22520\AppData\Local\Programs\Python\Python39\lib\site-packages\django\shortcuts.py", line 19, in render
    content = loader.render_to_string(template_name, context, request, using=using)
  File "C:\Users\22520\AppData\Local\Programs\Python\Python39\lib\site-packages\django\template\loader.py", line 62, in render_to_string
    return template.render(context, request)
  File "C:\Users\22520\AppData\Local\Programs\Python\Python39\lib\site-packages\django\template\backends\django.py", line 61, in render
    return self.template.render(context)
  File "C:\Users\22520\AppData\Local\Programs\Python\Python39\lib\site-packages\django\template\base.py", line 170, in render
    return self._render(context)
  File "C:\Users\22520\AppData\Local\Programs\Python\Python39\lib\site-packages\django\template\base.py", line 162, in _render
    return self.nodelist.render(context)
  File "C:\Users\22520\AppData\Local\Programs\Python\Python39\lib\site-packages\django\template\base.py", line 938, in render
    bit = node.render_annotated(context)
  File "C:\Users\22520\AppData\Local\Programs\Python\Python39\lib\site-packages\django\template\base.py", line 905, in render_annotated
    return self.render(context)
  File "C:\Users\22520\AppData\Local\Programs\Python\Python39\lib\site-packages\django\template\defaulttags.py", line 446, in render
    url = reverse(view_name, args=args, kwargs=kwargs, current_app=current_app)
  File "C:\Users\22520\AppData\Local\Programs\Python\Python39\lib\site-packages\django\urls\base.py", line 87, in reverse
    return iri_to_uri(resolver._reverse_with_prefix(view, prefix, *args, **kwargs))
  File "C:\Users\22520\AppData\Local\Programs\Python\Python39\lib\site-packages\django\urls\resolvers.py", line 685, in _reverse_with_prefix
    raise NoReverseMatch(msg)
django.urls.exceptions.NoReverseMatch: Reverse for 'Login' not found. 'Login' is not a valid view function or pattern name.
Internal Server Error: /login/
Traceback (most recent call last):
  File "C:\Users\22520\AppData\Local\Programs\Python\Python39\lib\site-packages\django\core\handlers\exception.py", line 47, in inner
    response = get_response(request)
  File "C:\Users\22520\AppData\Local\Programs\Python\Python39\lib\site-packages\django\core\handlers\base.py", line 179, in _get_response
    response = wrapped_callback(request, *callback_args, **callback_kwargs)
  File "D:\text1\zhigeng_Blog\Login\views.py", line 36, in login
    return render(request, 'Login.html')
  File "C:\Users\22520\AppData\Local\Programs\Python\Python39\lib\site-packages\django\shortcuts.py", line 19, in render
    content = loader.render_to_string(template_name, context, request, using=using)
  File "C:\Users\22520\AppData\Local\Programs\Python\Python39\lib\site-packages\django\template\loader.py", line 62, in render_to_string
    return template.render(context, request)
  File "C:\Users\22520\AppData\Local\Programs\Python\Python39\lib\site-packages\django\template\backends\django.py", line 61, in render
    return self.template.render(context)
  File "C:\Users\22520\AppData\Local\Programs\Python\Python39\lib\site-packages\django\template\base.py", line 170, in render
    return self._render(context)
  File "C:\Users\22520\AppData\Local\Programs\Python\Python39\lib\site-packages\django\template\base.py", line 162, in _render
    return self.nodelist.render(context)
  File "C:\Users\22520\AppData\Local\Programs\Python\Python39\lib\site-packages\django\template\base.py", line 938, in render
    bit = node.render_annotated(context)
  File "C:\Users\22520\AppData\Local\Programs\Python\Python39\lib\site-packages\django\template\base.py", line 905, in render_annotated
    return self.render(context)
  File "C:\Users\22520\AppData\Local\Programs\Python\Python39\lib\site-packages\django\template\defaulttags.py", line 446, in render
    url = reverse(view_name, args=args, kwargs=kwargs, current_app=current_app)
  File "C:\Users\22520\AppData\Local\Programs\Python\Python39\lib\site-packages\django\urls\base.py", line 87, in reverse
    return iri_to_uri(resolver._reverse_with_prefix(view, prefix, *args, **kwargs))
  File "C:\Users\22520\AppData\Local\Programs\Python\Python39\lib\site-packages\django\urls\resolvers.py", line 685, in _reverse_with_prefix
    raise NoReverseMatch(msg)
django.urls.exceptions.NoReverseMatch: Reverse for 'Login' not found. 'Login' is not a valid view function or pattern name.
Internal Server Error: /login/
Traceback (most recent call last):
  File "C:\Users\22520\AppData\Local\Programs\Python\Python39\lib\site-packages\django\core\handlers\exception.py", line 47, in inner
    response = get_response(request)
  File "C:\Users\22520\AppData\Local\Programs\Python\Python39\lib\site-packages\django\core\handlers\base.py", line 179, in _get_response
    response = wrapped_callback(request, *callback_args, **callback_kwargs)
  File "D:\text1\zhigeng_Blog\Login\views.py", line 36, in login
    return render(request, 'login.html')
  File "C:\Users\22520\AppData\Local\Programs\Python\Python39\lib\site-packages\django\shortcuts.py", line 19, in render
    content = loader.render_to_string(template_name, context, request, using=using)
  File "C:\Users\22520\AppData\Local\Programs\Python\Python39\lib\site-packages\django\template\loader.py", line 62, in render_to_string
    return template.render(context, request)
  File "C:\Users\22520\AppData\Local\Programs\Python\Python39\lib\site-packages\django\template\backends\django.py", line 61, in render
    return self.template.render(context)
  File "C:\Users\22520\AppData\Local\Programs\Python\Python39\lib\site-packages\django\template\base.py", line 170, in render
    return self._render(context)
  File "C:\Users\22520\AppData\Local\Programs\Python\Python39\lib\site-packages\django\template\base.py", line 162, in _render
    return self.nodelist.render(context)
  File "C:\Users\22520\AppData\Local\Programs\Python\Python39\lib\site-packages\django\template\base.py", line 938, in render
    bit = node.render_annotated(context)
  File "C:\Users\22520\AppData\Local\Programs\Python\Python39\lib\site-packages\django\template\base.py", line 905, in render_annotated
    return self.render(context)
  File "C:\Users\22520\AppData\Local\Programs\Python\Python39\lib\site-packages\django\template\defaulttags.py", line 446, in render
    url = reverse(view_name, args=args, kwargs=kwargs, current_app=current_app)
  File "C:\Users\22520\AppData\Local\Programs\Python\Python39\lib\site-packages\django\urls\base.py", line 87, in reverse
    return iri_to_uri(resolver._reverse_with_prefix(view, prefix, *args, **kwargs))
  File "C:\Users\22520\AppData\Local\Programs\Python\Python39\lib\site-packages\django\urls\resolvers.py", line 685, in _reverse_with_prefix
    raise NoReverseMatch(msg)
django.urls.exceptions.NoReverseMatch: Reverse for 'login' not found. 'login' is not a valid view function or pattern name.
Internal Server Error: /login/
Traceback (most recent call last):
  File "C:\Users\22520\AppData\Local\Programs\Python\Python39\lib\site-packages\django\core\handlers\exception.py", line 47, in inner
    response = get_response(request)
  File "C:\Users\22520\AppData\Local\Programs\Python\Python39\lib\site-packages\django\core\handlers\base.py", line 179, in _get_response
    response = wrapped_callback(request, *callback_args, **callback_kwargs)
  File "D:\text1\zhigeng_Blog\Login\views.py", line 36, in login
    return render(request, 'login.html')
  File "C:\Users\22520\AppData\Local\Programs\Python\Python39\lib\site-packages\django\shortcuts.py", line 19, in render
    content = loader.render_to_string(template_name, context, request, using=using)
  File "C:\Users\22520\AppData\Local\Programs\Python\Python39\lib\site-packages\django\template\loader.py", line 62, in render_to_string
    return template.render(context, request)
  File "C:\Users\22520\AppData\Local\Programs\Python\Python39\lib\site-packages\django\template\backends\django.py", line 61, in render
    return self.template.render(context)
  File "C:\Users\22520\AppData\Local\Programs\Python\Python39\lib\site-packages\django\template\base.py", line 170, in render
    return self._render(context)
  File "C:\Users\22520\AppData\Local\Programs\Python\Python39\lib\site-packages\django\template\base.py", line 162, in _render
    return self.nodelist.render(context)
  File "C:\Users\22520\AppData\Local\Programs\Python\Python39\lib\site-packages\django\template\base.py", line 938, in render
    bit = node.render_annotated(context)
  File "C:\Users\22520\AppData\Local\Programs\Python\Python39\lib\site-packages\django\template\base.py", line 905, in render_annotated
    return self.render(context)
  File "C:\Users\22520\AppData\Local\Programs\Python\Python39\lib\site-packages\django\template\defaulttags.py", line 446, in render
    url = reverse(view_name, args=args, kwargs=kwargs, current_app=current_app)
  File "C:\Users\22520\AppData\Local\Programs\Python\Python39\lib\site-packages\django\urls\base.py", line 87, in reverse
    return iri_to_uri(resolver._reverse_with_prefix(view, prefix, *args, **kwargs))
  File "C:\Users\22520\AppData\Local\Programs\Python\Python39\lib\site-packages\django\urls\resolvers.py", line 685, in _reverse_with_prefix
    raise NoReverseMatch(msg)
django.urls.exceptions.NoReverseMatch: Reverse for 'login' not found. 'login' is not a valid view function or pattern name.
Internal Server Error: /login/
Traceback (most recent call last):
  File "C:\Users\22520\AppData\Local\Programs\Python\Python39\lib\site-packages\django\core\handlers\exception.py", line 47, in inner
    response = get_response(request)
  File "C:\Users\22520\AppData\Local\Programs\Python\Python39\lib\site-packages\django\core\handlers\base.py", line 179, in _get_response
    response = wrapped_callback(request, *callback_args, **callback_kwargs)
  File "D:\text1\zhigeng_Blog\Login\views.py", line 36, in login
    return render(request, 'login.html')
  File "C:\Users\22520\AppData\Local\Programs\Python\Python39\lib\site-packages\django\shortcuts.py", line 19, in render
    content = loader.render_to_string(template_name, context, request, using=using)
  File "C:\Users\22520\AppData\Local\Programs\Python\Python39\lib\site-packages\django\template\loader.py", line 62, in render_to_string
    return template.render(context, request)
  File "C:\Users\22520\AppData\Local\Programs\Python\Python39\lib\site-packages\django\template\backends\django.py", line 61, in render
    return self.template.render(context)
  File "C:\Users\22520\AppData\Local\Programs\Python\Python39\lib\site-packages\django\template\base.py", line 170, in render
    return self._render(context)
  File "C:\Users\22520\AppData\Local\Programs\Python\Python39\lib\site-packages\django\template\base.py", line 162, in _render
    return self.nodelist.render(context)
  File "C:\Users\22520\AppData\Local\Programs\Python\Python39\lib\site-packages\django\template\base.py", line 938, in render
    bit = node.render_annotated(context)
  File "C:\Users\22520\AppData\Local\Programs\Python\Python39\lib\site-packages\django\template\base.py", line 905, in render_annotated
    return self.render(context)
  File "C:\Users\22520\AppData\Local\Programs\Python\Python39\lib\site-packages\django\template\defaulttags.py", line 446, in render
    url = reverse(view_name, args=args, kwargs=kwargs, current_app=current_app)
  File "C:\Users\22520\AppData\Local\Programs\Python\Python39\lib\site-packages\django\urls\base.py", line 87, in reverse
    return iri_to_uri(resolver._reverse_with_prefix(view, prefix, *args, **kwargs))
  File "C:\Users\22520\AppData\Local\Programs\Python\Python39\lib\site-packages\django\urls\resolvers.py", line 685, in _reverse_with_prefix
    raise NoReverseMatch(msg)
django.urls.exceptions.NoReverseMatch: Reverse for 'login.html' not found. 'login.html' is not a valid view function or pattern name.
Internal Server Error: /login/
Traceback (most recent call last):
  File "C:\Users\22520\AppData\Local\Programs\Python\Python39\lib\site-packages\django\core\handlers\exception.py", line 47, in inner
    response = get_response(request)
  File "C:\Users\22520\AppData\Local\Programs\Python\Python39\lib\site-packages\django\core\handlers\base.py", line 186, in _get_response
    self.check_response(response, callback)
  File "C:\Users\22520\AppData\Local\Programs\Python\Python39\lib\site-packages\django\core\handlers\base.py", line 307, in check_response
    raise ValueError(
ValueError: The view Login.views.login didn't return an HttpResponse object. It returned None instead.
Internal Server Error: /login/
Traceback (most recent call last):
  File "C:\Users\22520\AppData\Local\Programs\Python\Python39\lib\site-packages\django\core\handlers\exception.py", line 47, in inner
    response = get_response(request)
  File "C:\Users\22520\AppData\Local\Programs\Python\Python39\lib\site-packages\django\core\handlers\base.py", line 179, in _get_response
    response = wrapped_callback(request, *callback_args, **callback_kwargs)
  File "D:\text1\zhigeng_Blog\Login\views.py", line 36, in login
    return render(request, 'login.html')
  File "C:\Users\22520\AppData\Local\Programs\Python\Python39\lib\site-packages\django\shortcuts.py", line 19, in render
    content = loader.render_to_string(template_name, context, request, using=using)
  File "C:\Users\22520\AppData\Local\Programs\Python\Python39\lib\site-packages\django\template\loader.py", line 62, in render_to_string
    return template.render(context, request)
  File "C:\Users\22520\AppData\Local\Programs\Python\Python39\lib\site-packages\django\template\backends\django.py", line 61, in render
    return self.template.render(context)
  File "C:\Users\22520\AppData\Local\Programs\Python\Python39\lib\site-packages\django\template\base.py", line 170, in render
    return self._render(context)
  File "C:\Users\22520\AppData\Local\Programs\Python\Python39\lib\site-packages\django\template\base.py", line 162, in _render
    return self.nodelist.render(context)
  File "C:\Users\22520\AppData\Local\Programs\Python\Python39\lib\site-packages\django\template\base.py", line 938, in render
    bit = node.render_annotated(context)
  File "C:\Users\22520\AppData\Local\Programs\Python\Python39\lib\site-packages\django\template\base.py", line 905, in render_annotated
    return self.render(context)
  File "C:\Users\22520\AppData\Local\Programs\Python\Python39\lib\site-packages\django\template\defaulttags.py", line 446, in render
    url = reverse(view_name, args=args, kwargs=kwargs, current_app=current_app)
  File "C:\Users\22520\AppData\Local\Programs\Python\Python39\lib\site-packages\django\urls\base.py", line 87, in reverse
    return iri_to_uri(resolver._reverse_with_prefix(view, prefix, *args, **kwargs))
  File "C:\Users\22520\AppData\Local\Programs\Python\Python39\lib\site-packages\django\urls\resolvers.py", line 685, in _reverse_with_prefix
    raise NoReverseMatch(msg)
django.urls.exceptions.NoReverseMatch: Reverse for 'login' not found. 'login' is not a valid view function or pattern name.
Internal Server Error: /login/
Traceback (most recent call last):
  File "C:\Users\22520\AppData\Local\Programs\Python\Python39\lib\site-packages\django\core\handlers\exception.py", line 47, in inner
    response = get_response(request)
  File "C:\Users\22520\AppData\Local\Programs\Python\Python39\lib\site-packages\django\core\handlers\base.py", line 179, in _get_response
    response = wrapped_callback(request, *callback_args, **callback_kwargs)
  File "D:\text1\zhigeng_Blog\Login\views.py", line 36, in login
    return render(request, 'login.html')
  File "C:\Users\22520\AppData\Local\Programs\Python\Python39\lib\site-packages\django\shortcuts.py", line 19, in render
    content = loader.render_to_string(template_name, context, request, using=using)
  File "C:\Users\22520\AppData\Local\Programs\Python\Python39\lib\site-packages\django\template\loader.py", line 62, in render_to_string
    return template.render(context, request)
  File "C:\Users\22520\AppData\Local\Programs\Python\Python39\lib\site-packages\django\template\backends\django.py", line 61, in render
    return self.template.render(context)
  File "C:\Users\22520\AppData\Local\Programs\Python\Python39\lib\site-packages\django\template\base.py", line 170, in render
    return self._render(context)
  File "C:\Users\22520\AppData\Local\Programs\Python\Python39\lib\site-packages\django\template\base.py", line 162, in _render
    return self.nodelist.render(context)
  File "C:\Users\22520\AppData\Local\Programs\Python\Python39\lib\site-packages\django\template\base.py", line 938, in render
    bit = node.render_annotated(context)
  File "C:\Users\22520\AppData\Local\Programs\Python\Python39\lib\site-packages\django\template\base.py", line 905, in render_annotated
    return self.render(context)
  File "C:\Users\22520\AppData\Local\Programs\Python\Python39\lib\site-packages\django\template\defaulttags.py", line 446, in render
    url = reverse(view_name, args=args, kwargs=kwargs, current_app=current_app)
  File "C:\Users\22520\AppData\Local\Programs\Python\Python39\lib\site-packages\django\urls\base.py", line 87, in reverse
    return iri_to_uri(resolver._reverse_with_prefix(view, prefix, *args, **kwargs))
  File "C:\Users\22520\AppData\Local\Programs\Python\Python39\lib\site-packages\django\urls\resolvers.py", line 685, in _reverse_with_prefix
    raise NoReverseMatch(msg)
django.urls.exceptions.NoReverseMatch: Reverse for 'login' not found. 'login' is not a valid view function or pattern name.
Internal Server Error: /login/
Traceback (most recent call last):
  File "C:\Users\22520\AppData\Local\Programs\Python\Python39\lib\site-packages\django\core\handlers\exception.py", line 47, in inner
    response = get_response(request)
  File "C:\Users\22520\AppData\Local\Programs\Python\Python39\lib\site-packages\django\core\handlers\base.py", line 179, in _get_response
    response = wrapped_callback(request, *callback_args, **callback_kwargs)
  File "D:\text1\zhigeng_Blog\Login\views.py", line 36, in login
    return render(request, 'login.html')
  File "C:\Users\22520\AppData\Local\Programs\Python\Python39\lib\site-packages\django\shortcuts.py", line 19, in render
    content = loader.render_to_string(template_name, context, request, using=using)
  File "C:\Users\22520\AppData\Local\Programs\Python\Python39\lib\site-packages\django\template\loader.py", line 62, in render_to_string
    return template.render(context, request)
  File "C:\Users\22520\AppData\Local\Programs\Python\Python39\lib\site-packages\django\template\backends\django.py", line 61, in render
    return self.template.render(context)
  File "C:\Users\22520\AppData\Local\Programs\Python\Python39\lib\site-packages\django\template\base.py", line 170, in render
    return self._render(context)
  File "C:\Users\22520\AppData\Local\Programs\Python\Python39\lib\site-packages\django\template\base.py", line 162, in _render
    return self.nodelist.render(context)
  File "C:\Users\22520\AppData\Local\Programs\Python\Python39\lib\site-packages\django\template\base.py", line 938, in render
    bit = node.render_annotated(context)
  File "C:\Users\22520\AppData\Local\Programs\Python\Python39\lib\site-packages\django\template\base.py", line 905, in render_annotated
    return self.render(context)
  File "C:\Users\22520\AppData\Local\Programs\Python\Python39\lib\site-packages\django\template\defaulttags.py", line 446, in render
    url = reverse(view_name, args=args, kwargs=kwargs, current_app=current_app)
  File "C:\Users\22520\AppData\Local\Programs\Python\Python39\lib\site-packages\django\urls\base.py", line 87, in reverse
    return iri_to_uri(resolver._reverse_with_prefix(view, prefix, *args, **kwargs))
  File "C:\Users\22520\AppData\Local\Programs\Python\Python39\lib\site-packages\django\urls\resolvers.py", line 685, in _reverse_with_prefix
    raise NoReverseMatch(msg)
django.urls.exceptions.NoReverseMatch: Reverse for 'login' not found. 'login' is not a valid view function or pattern name.
Internal Server Error: /login/
Traceback (most recent call last):
  File "C:\Users\22520\AppData\Local\Programs\Python\Python39\lib\site-packages\django\core\handlers\exception.py", line 47, in inner
    response = get_response(request)
  File "C:\Users\22520\AppData\Local\Programs\Python\Python39\lib\site-packages\django\core\handlers\base.py", line 179, in _get_response
    response = wrapped_callback(request, *callback_args, **callback_kwargs)
  File "D:\text1\zhigeng_Blog\Login\views.py", line 36, in login
    return render(request, 'login.html')
  File "C:\Users\22520\AppData\Local\Programs\Python\Python39\lib\site-packages\django\shortcuts.py", line 19, in render
    content = loader.render_to_string(template_name, context, request, using=using)
  File "C:\Users\22520\AppData\Local\Programs\Python\Python39\lib\site-packages\django\template\loader.py", line 62, in render_to_string
    return template.render(context, request)
  File "C:\Users\22520\AppData\Local\Programs\Python\Python39\lib\site-packages\django\template\backends\django.py", line 61, in render
    return self.template.render(context)
  File "C:\Users\22520\AppData\Local\Programs\Python\Python39\lib\site-packages\django\template\base.py", line 170, in render
    return self._render(context)
  File "C:\Users\22520\AppData\Local\Programs\Python\Python39\lib\site-packages\django\template\base.py", line 162, in _render
    return self.nodelist.render(context)
  File "C:\Users\22520\AppData\Local\Programs\Python\Python39\lib\site-packages\django\template\base.py", line 938, in render
    bit = node.render_annotated(context)
  File "C:\Users\22520\AppData\Local\Programs\Python\Python39\lib\site-packages\django\template\base.py", line 905, in render_annotated
    return self.render(context)
  File "C:\Users\22520\AppData\Local\Programs\Python\Python39\lib\site-packages\django\template\defaulttags.py", line 446, in render
    url = reverse(view_name, args=args, kwargs=kwargs, current_app=current_app)
  File "C:\Users\22520\AppData\Local\Programs\Python\Python39\lib\site-packages\django\urls\base.py", line 87, in reverse
    return iri_to_uri(resolver._reverse_with_prefix(view, prefix, *args, **kwargs))
  File "C:\Users\22520\AppData\Local\Programs\Python\Python39\lib\site-packages\django\urls\resolvers.py", line 685, in _reverse_with_prefix
    raise NoReverseMatch(msg)
django.urls.exceptions.NoReverseMatch: Reverse for 'login' not found. 'login' is not a valid view function or pattern name.
Internal Server Error: /login/
Traceback (most recent call last):
  File "C:\Users\22520\AppData\Local\Programs\Python\Python39\lib\site-packages\django\core\handlers\exception.py", line 47, in inner
    response = get_response(request)
  File "C:\Users\22520\AppData\Local\Programs\Python\Python39\lib\site-packages\django\core\handlers\base.py", line 179, in _get_response
    response = wrapped_callback(request, *callback_args, **callback_kwargs)
  File "D:\text1\zhigeng_Blog\Login\views.py", line 36, in login
    return render(request, 'login.html')
  File "C:\Users\22520\AppData\Local\Programs\Python\Python39\lib\site-packages\django\shortcuts.py", line 19, in render
    content = loader.render_to_string(template_name, context, request, using=using)
  File "C:\Users\22520\AppData\Local\Programs\Python\Python39\lib\site-packages\django\template\loader.py", line 62, in render_to_string
    return template.render(context, request)
  File "C:\Users\22520\AppData\Local\Programs\Python\Python39\lib\site-packages\django\template\backends\django.py", line 61, in render
    return self.template.render(context)
  File "C:\Users\22520\AppData\Local\Programs\Python\Python39\lib\site-packages\django\template\base.py", line 170, in render
    return self._render(context)
  File "C:\Users\22520\AppData\Local\Programs\Python\Python39\lib\site-packages\django\template\base.py", line 162, in _render
    return self.nodelist.render(context)
  File "C:\Users\22520\AppData\Local\Programs\Python\Python39\lib\site-packages\django\template\base.py", line 938, in render
    bit = node.render_annotated(context)
  File "C:\Users\22520\AppData\Local\Programs\Python\Python39\lib\site-packages\django\template\base.py", line 905, in render_annotated
    return self.render(context)
  File "C:\Users\22520\AppData\Local\Programs\Python\Python39\lib\site-packages\django\template\defaulttags.py", line 446, in render
    url = reverse(view_name, args=args, kwargs=kwargs, current_app=current_app)
  File "C:\Users\22520\AppData\Local\Programs\Python\Python39\lib\site-packages\django\urls\base.py", line 87, in reverse
    return iri_to_uri(resolver._reverse_with_prefix(view, prefix, *args, **kwargs))
  File "C:\Users\22520\AppData\Local\Programs\Python\Python39\lib\site-packages\django\urls\resolvers.py", line 685, in _reverse_with_prefix
    raise NoReverseMatch(msg)
django.urls.exceptions.NoReverseMatch: Reverse for 'login' not found. 'login' is not a valid view function or pattern name.
Internal Server Error: /login/
Traceback (most recent call last):
  File "C:\Users\22520\AppData\Local\Programs\Python\Python39\lib\site-packages\django\core\handlers\exception.py", line 47, in inner
    response = get_response(request)
  File "C:\Users\22520\AppData\Local\Programs\Python\Python39\lib\site-packages\django\core\handlers\base.py", line 179, in _get_response
    response = wrapped_callback(request, *callback_args, **callback_kwargs)
  File "D:\text1\zhigeng_Blog\Login\views.py", line 36, in login
    return render(request, 'login.html')
  File "C:\Users\22520\AppData\Local\Programs\Python\Python39\lib\site-packages\django\shortcuts.py", line 19, in render
    content = loader.render_to_string(template_name, context, request, using=using)
  File "C:\Users\22520\AppData\Local\Programs\Python\Python39\lib\site-packages\django\template\loader.py", line 62, in render_to_string
    return template.render(context, request)
  File "C:\Users\22520\AppData\Local\Programs\Python\Python39\lib\site-packages\django\template\backends\django.py", line 61, in render
    return self.template.render(context)
  File "C:\Users\22520\AppData\Local\Programs\Python\Python39\lib\site-packages\django\template\base.py", line 170, in render
    return self._render(context)
  File "C:\Users\22520\AppData\Local\Programs\Python\Python39\lib\site-packages\django\template\base.py", line 162, in _render
    return self.nodelist.render(context)
  File "C:\Users\22520\AppData\Local\Programs\Python\Python39\lib\site-packages\django\template\base.py", line 938, in render
    bit = node.render_annotated(context)
  File "C:\Users\22520\AppData\Local\Programs\Python\Python39\lib\site-packages\django\template\base.py", line 905, in render_annotated
    return self.render(context)
  File "C:\Users\22520\AppData\Local\Programs\Python\Python39\lib\site-packages\django\template\defaulttags.py", line 446, in render
    url = reverse(view_name, args=args, kwargs=kwargs, current_app=current_app)
  File "C:\Users\22520\AppData\Local\Programs\Python\Python39\lib\site-packages\django\urls\base.py", line 87, in reverse
    return iri_to_uri(resolver._reverse_with_prefix(view, prefix, *args, **kwargs))
  File "C:\Users\22520\AppData\Local\Programs\Python\Python39\lib\site-packages\django\urls\resolvers.py", line 685, in _reverse_with_prefix
    raise NoReverseMatch(msg)
django.urls.exceptions.NoReverseMatch: Reverse for 'login' not found. 'login' is not a valid view function or pattern name.
Internal Server Error: /login/
Traceback (most recent call last):
  File "C:\Users\22520\AppData\Local\Programs\Python\Python39\lib\site-packages\django\core\handlers\exception.py", line 47, in inner
    response = get_response(request)
  File "C:\Users\22520\AppData\Local\Programs\Python\Python39\lib\site-packages\django\core\handlers\base.py", line 179, in _get_response
    response = wrapped_callback(request, *callback_args, **callback_kwargs)
  File "D:\text1\zhigeng_Blog\Login\views.py", line 36, in login
    return render(request, 'login.html')
  File "C:\Users\22520\AppData\Local\Programs\Python\Python39\lib\site-packages\django\shortcuts.py", line 19, in render
    content = loader.render_to_string(template_name, context, request, using=using)
  File "C:\Users\22520\AppData\Local\Programs\Python\Python39\lib\site-packages\django\template\loader.py", line 62, in render_to_string
    return template.render(context, request)
  File "C:\Users\22520\AppData\Local\Programs\Python\Python39\lib\site-packages\django\template\backends\django.py", line 61, in render
    return self.template.render(context)
  File "C:\Users\22520\AppData\Local\Programs\Python\Python39\lib\site-packages\django\template\base.py", line 170, in render
    return self._render(context)
  File "C:\Users\22520\AppData\Local\Programs\Python\Python39\lib\site-packages\django\template\base.py", line 162, in _render
    return self.nodelist.render(context)
  File "C:\Users\22520\AppData\Local\Programs\Python\Python39\lib\site-packages\django\template\base.py", line 938, in render
    bit = node.render_annotated(context)
  File "C:\Users\22520\AppData\Local\Programs\Python\Python39\lib\site-packages\django\template\base.py", line 905, in render_annotated
    return self.render(context)
  File "C:\Users\22520\AppData\Local\Programs\Python\Python39\lib\site-packages\django\template\defaulttags.py", line 446, in render
    url = reverse(view_name, args=args, kwargs=kwargs, current_app=current_app)
  File "C:\Users\22520\AppData\Local\Programs\Python\Python39\lib\site-packages\django\urls\base.py", line 87, in reverse
    return iri_to_uri(resolver._reverse_with_prefix(view, prefix, *args, **kwargs))
  File "C:\Users\22520\AppData\Local\Programs\Python\Python39\lib\site-packages\django\urls\resolvers.py", line 685, in _reverse_with_prefix
    raise NoReverseMatch(msg)
django.urls.exceptions.NoReverseMatch: Reverse for 'login' not found. 'login' is not a valid view function or pattern name.
Internal Server Error: /login/
Traceback (most recent call last):
  File "C:\Users\22520\AppData\Local\Programs\Python\Python39\lib\site-packages\django\core\handlers\exception.py", line 47, in inner
    response = get_response(request)
  File "C:\Users\22520\AppData\Local\Programs\Python\Python39\lib\site-packages\django\core\handlers\base.py", line 179, in _get_response
    response = wrapped_callback(request, *callback_args, **callback_kwargs)
  File "D:\text1\zhigeng_Blog\Login\views.py", line 36, in login
    return render(request, 'login.html')
  File "C:\Users\22520\AppData\Local\Programs\Python\Python39\lib\site-packages\django\shortcuts.py", line 19, in render
    content = loader.render_to_string(template_name, context, request, using=using)
  File "C:\Users\22520\AppData\Local\Programs\Python\Python39\lib\site-packages\django\template\loader.py", line 62, in render_to_string
    return template.render(context, request)
  File "C:\Users\22520\AppData\Local\Programs\Python\Python39\lib\site-packages\django\template\backends\django.py", line 61, in render
    return self.template.render(context)
  File "C:\Users\22520\AppData\Local\Programs\Python\Python39\lib\site-packages\django\template\base.py", line 170, in render
    return self._render(context)
  File "C:\Users\22520\AppData\Local\Programs\Python\Python39\lib\site-packages\django\template\base.py", line 162, in _render
    return self.nodelist.render(context)
  File "C:\Users\22520\AppData\Local\Programs\Python\Python39\lib\site-packages\django\template\base.py", line 938, in render
    bit = node.render_annotated(context)
  File "C:\Users\22520\AppData\Local\Programs\Python\Python39\lib\site-packages\django\template\base.py", line 905, in render_annotated
    return self.render(context)
  File "C:\Users\22520\AppData\Local\Programs\Python\Python39\lib\site-packages\django\template\defaulttags.py", line 446, in render
    url = reverse(view_name, args=args, kwargs=kwargs, current_app=current_app)
  File "C:\Users\22520\AppData\Local\Programs\Python\Python39\lib\site-packages\django\urls\base.py", line 87, in reverse
    return iri_to_uri(resolver._reverse_with_prefix(view, prefix, *args, **kwargs))
  File "C:\Users\22520\AppData\Local\Programs\Python\Python39\lib\site-packages\django\urls\resolvers.py", line 685, in _reverse_with_prefix
    raise NoReverseMatch(msg)
django.urls.exceptions.NoReverseMatch: Reverse for 'login' not found. 'login' is not a valid view function or pattern name.
Internal Server Error: /login/register.html
Traceback (most recent call last):
  File "C:\Users\22520\AppData\Local\Programs\Python\Python39\lib\site-packages\django\core\handlers\exception.py", line 47, in inner
    response = get_response(request)
  File "C:\Users\22520\AppData\Local\Programs\Python\Python39\lib\site-packages\django\core\handlers\base.py", line 179, in _get_response
    response = wrapped_callback(request, *callback_args, **callback_kwargs)
  File "D:\text1\zhigeng_Blog\Login\views.py", line 36, in login
    return render(request, 'login.html')
  File "C:\Users\22520\AppData\Local\Programs\Python\Python39\lib\site-packages\django\shortcuts.py", line 19, in render
    content = loader.render_to_string(template_name, context, request, using=using)
  File "C:\Users\22520\AppData\Local\Programs\Python\Python39\lib\site-packages\django\template\loader.py", line 62, in render_to_string
    return template.render(context, request)
  File "C:\Users\22520\AppData\Local\Programs\Python\Python39\lib\site-packages\django\template\backends\django.py", line 61, in render
    return self.template.render(context)
  File "C:\Users\22520\AppData\Local\Programs\Python\Python39\lib\site-packages\django\template\base.py", line 170, in render
    return self._render(context)
  File "C:\Users\22520\AppData\Local\Programs\Python\Python39\lib\site-packages\django\template\base.py", line 162, in _render
    return self.nodelist.render(context)
  File "C:\Users\22520\AppData\Local\Programs\Python\Python39\lib\site-packages\django\template\base.py", line 938, in render
    bit = node.render_annotated(context)
  File "C:\Users\22520\AppData\Local\Programs\Python\Python39\lib\site-packages\django\template\base.py", line 905, in render_annotated
    return self.render(context)
  File "C:\Users\22520\AppData\Local\Programs\Python\Python39\lib\site-packages\django\template\defaulttags.py", line 446, in render
    url = reverse(view_name, args=args, kwargs=kwargs, current_app=current_app)
  File "C:\Users\22520\AppData\Local\Programs\Python\Python39\lib\site-packages\django\urls\base.py", line 87, in reverse
    return iri_to_uri(resolver._reverse_with_prefix(view, prefix, *args, **kwargs))
  File "C:\Users\22520\AppData\Local\Programs\Python\Python39\lib\site-packages\django\urls\resolvers.py", line 685, in _reverse_with_prefix
    raise NoReverseMatch(msg)
django.urls.exceptions.NoReverseMatch: Reverse for 'login' not found. 'login' is not a valid view function or pattern name.
Internal Server Error: /login/register.html
Traceback (most recent call last):
  File "C:\Users\22520\AppData\Local\Programs\Python\Python39\lib\site-packages\django\core\handlers\exception.py", line 47, in inner
    response = get_response(request)
  File "C:\Users\22520\AppData\Local\Programs\Python\Python39\lib\site-packages\django\core\handlers\base.py", line 179, in _get_response
    response = wrapped_callback(request, *callback_args, **callback_kwargs)
  File "D:\text1\zhigeng_Blog\Login\views.py", line 13, in login
    return render(request, 'login/login.html')
  File "C:\Users\22520\AppData\Local\Programs\Python\Python39\lib\site-packages\django\shortcuts.py", line 19, in render
    content = loader.render_to_string(template_name, context, request, using=using)
  File "C:\Users\22520\AppData\Local\Programs\Python\Python39\lib\site-packages\django\template\loader.py", line 61, in render_to_string
    template = get_template(template_name, using=using)
  File "C:\Users\22520\AppData\Local\Programs\Python\Python39\lib\site-packages\django\template\loader.py", line 19, in get_template
    raise TemplateDoesNotExist(template_name, chain=chain)
django.template.exceptions.TemplateDoesNotExist: login/login.html
Internal Server Error: /login/register.html
Traceback (most recent call last):
  File "C:\Users\22520\AppData\Local\Programs\Python\Python39\lib\site-packages\django\core\handlers\exception.py", line 47, in inner
    response = get_response(request)
  File "C:\Users\22520\AppData\Local\Programs\Python\Python39\lib\site-packages\django\core\handlers\base.py", line 179, in _get_response
    response = wrapped_callback(request, *callback_args, **callback_kwargs)
  File "D:\text1\zhigeng_Blog\Login\views.py", line 13, in login
    return render(request, 'login/login.html')
  File "C:\Users\22520\AppData\Local\Programs\Python\Python39\lib\site-packages\django\shortcuts.py", line 19, in render
    content = loader.render_to_string(template_name, context, request, using=using)
  File "C:\Users\22520\AppData\Local\Programs\Python\Python39\lib\site-packages\django\template\loader.py", line 61, in render_to_string
    template = get_template(template_name, using=using)
  File "C:\Users\22520\AppData\Local\Programs\Python\Python39\lib\site-packages\django\template\loader.py", line 19, in get_template
    raise TemplateDoesNotExist(template_name, chain=chain)
django.template.exceptions.TemplateDoesNotExist: login/login.html
Internal Server Error: /login/register.html
Traceback (most recent call last):
  File "C:\Users\22520\AppData\Local\Programs\Python\Python39\lib\site-packages\django\core\handlers\exception.py", line 47, in inner
    response = get_response(request)
  File "C:\Users\22520\AppData\Local\Programs\Python\Python39\lib\site-packages\django\core\handlers\base.py", line 179, in _get_response
    response = wrapped_callback(request, *callback_args, **callback_kwargs)
  File "D:\text1\zhigeng_Blog\Login\views.py", line 13, in login
    return render(request, 'login/login.html')
  File "C:\Users\22520\AppData\Local\Programs\Python\Python39\lib\site-packages\django\shortcuts.py", line 19, in render
    content = loader.render_to_string(template_name, context, request, using=using)
  File "C:\Users\22520\AppData\Local\Programs\Python\Python39\lib\site-packages\django\template\loader.py", line 61, in render_to_string
    template = get_template(template_name, using=using)
  File "C:\Users\22520\AppData\Local\Programs\Python\Python39\lib\site-packages\django\template\loader.py", line 19, in get_template
    raise TemplateDoesNotExist(template_name, chain=chain)
django.template.exceptions.TemplateDoesNotExist: login/login.html
Internal Server Error: /login/register.html
Traceback (most recent call last):
  File "C:\Users\22520\AppData\Local\Programs\Python\Python39\lib\site-packages\django\core\handlers\exception.py", line 47, in inner
    response = get_response(request)
  File "C:\Users\22520\AppData\Local\Programs\Python\Python39\lib\site-packages\django\core\handlers\base.py", line 179, in _get_response
    response = wrapped_callback(request, *callback_args, **callback_kwargs)
  File "D:\text1\zhigeng_Blog\Login\views.py", line 13, in login
    return render(request, 'login/login.html')
  File "C:\Users\22520\AppData\Local\Programs\Python\Python39\lib\site-packages\django\shortcuts.py", line 19, in render
    content = loader.render_to_string(template_name, context, request, using=using)
  File "C:\Users\22520\AppData\Local\Programs\Python\Python39\lib\site-packages\django\template\loader.py", line 61, in render_to_string
    template = get_template(template_name, using=using)
  File "C:\Users\22520\AppData\Local\Programs\Python\Python39\lib\site-packages\django\template\loader.py", line 19, in get_template
    raise TemplateDoesNotExist(template_name, chain=chain)
django.template.exceptions.TemplateDoesNotExist: login/login.html
Internal Server Error: /login/register.html
Traceback (most recent call last):
  File "C:\Users\22520\AppData\Local\Programs\Python\Python39\lib\site-packages\django\core\handlers\exception.py", line 47, in inner
    response = get_response(request)
  File "C:\Users\22520\AppData\Local\Programs\Python\Python39\lib\site-packages\django\core\handlers\base.py", line 179, in _get_response
    response = wrapped_callback(request, *callback_args, **callback_kwargs)
  File "D:\text1\zhigeng_Blog\Login\views.py", line 13, in login
    return render(request, 'login/login.html')
  File "C:\Users\22520\AppData\Local\Programs\Python\Python39\lib\site-packages\django\shortcuts.py", line 19, in render
    content = loader.render_to_string(template_name, context, request, using=using)
  File "C:\Users\22520\AppData\Local\Programs\Python\Python39\lib\site-packages\django\template\loader.py", line 61, in render_to_string
    template = get_template(template_name, using=using)
  File "C:\Users\22520\AppData\Local\Programs\Python\Python39\lib\site-packages\django\template\loader.py", line 19, in get_template
    raise TemplateDoesNotExist(template_name, chain=chain)
django.template.exceptions.TemplateDoesNotExist: login/login.html
Internal Server Error: /login/register.html
Traceback (most recent call last):
  File "C:\Users\22520\AppData\Local\Programs\Python\Python39\lib\site-packages\django\core\handlers\exception.py", line 47, in inner
    response = get_response(request)
  File "C:\Users\22520\AppData\Local\Programs\Python\Python39\lib\site-packages\django\core\handlers\base.py", line 179, in _get_response
    response = wrapped_callback(request, *callback_args, **callback_kwargs)
  File "D:\text1\zhigeng_Blog\Login\views.py", line 13, in login
    return render(request, 'login/login.html')
  File "C:\Users\22520\AppData\Local\Programs\Python\Python39\lib\site-packages\django\shortcuts.py", line 19, in render
    content = loader.render_to_string(template_name, context, request, using=using)
  File "C:\Users\22520\AppData\Local\Programs\Python\Python39\lib\site-packages\django\template\loader.py", line 61, in render_to_string
    template = get_template(template_name, using=using)
  File "C:\Users\22520\AppData\Local\Programs\Python\Python39\lib\site-packages\django\template\loader.py", line 19, in get_template
    raise TemplateDoesNotExist(template_name, chain=chain)
django.template.exceptions.TemplateDoesNotExist: login/login.html
Internal Server Error: /login/register.html
Traceback (most recent call last):
  File "C:\Users\22520\AppData\Local\Programs\Python\Python39\lib\site-packages\django\core\handlers\exception.py", line 47, in inner
    response = get_response(request)
  File "C:\Users\22520\AppData\Local\Programs\Python\Python39\lib\site-packages\django\core\handlers\base.py", line 179, in _get_response
    response = wrapped_callback(request, *callback_args, **callback_kwargs)
  File "D:\text1\zhigeng_Blog\Login\views.py", line 13, in login
    return render(request, 'login/login.html')
  File "C:\Users\22520\AppData\Local\Programs\Python\Python39\lib\site-packages\django\shortcuts.py", line 19, in render
    content = loader.render_to_string(template_name, context, request, using=using)
  File "C:\Users\22520\AppData\Local\Programs\Python\Python39\lib\site-packages\django\template\loader.py", line 61, in render_to_string
    template = get_template(template_name, using=using)
  File "C:\Users\22520\AppData\Local\Programs\Python\Python39\lib\site-packages\django\template\loader.py", line 19, in get_template
    raise TemplateDoesNotExist(template_name, chain=chain)
django.template.exceptions.TemplateDoesNotExist: login/login.html
Internal Server Error: /login/register.html
Traceback (most recent call last):
  File "C:\Users\22520\AppData\Local\Programs\Python\Python39\lib\site-packages\django\core\handlers\exception.py", line 47, in inner
    response = get_response(request)
  File "C:\Users\22520\AppData\Local\Programs\Python\Python39\lib\site-packages\django\core\handlers\base.py", line 179, in _get_response
    response = wrapped_callback(request, *callback_args, **callback_kwargs)
  File "D:\text1\zhigeng_Blog\Login\views.py", line 13, in login
    return render(request, 'login/login.html')
  File "C:\Users\22520\AppData\Local\Programs\Python\Python39\lib\site-packages\django\shortcuts.py", line 19, in render
    content = loader.render_to_string(template_name, context, request, using=using)
  File "C:\Users\22520\AppData\Local\Programs\Python\Python39\lib\site-packages\django\template\loader.py", line 61, in render_to_string
    template = get_template(template_name, using=using)
  File "C:\Users\22520\AppData\Local\Programs\Python\Python39\lib\site-packages\django\template\loader.py", line 19, in get_template
    raise TemplateDoesNotExist(template_name, chain=chain)
django.template.exceptions.TemplateDoesNotExist: login/login.html
Internal Server Error: /login/
Traceback (most recent call last):
  File "C:\Users\22520\AppData\Local\Programs\Python\Python39\lib\site-packages\django\core\handlers\exception.py", line 47, in inner
    response = get_response(request)
  File "C:\Users\22520\AppData\Local\Programs\Python\Python39\lib\site-packages\django\core\handlers\base.py", line 179, in _get_response
    response = wrapped_callback(request, *callback_args, **callback_kwargs)
TypeError: login() missing 1 required positional argument: 'user'
Internal Server Error: /login/
Traceback (most recent call last):
  File "C:\Users\22520\AppData\Local\Programs\Python\Python39\lib\site-packages\django\core\handlers\exception.py", line 47, in inner
    response = get_response(request)
  File "C:\Users\22520\AppData\Local\Programs\Python\Python39\lib\site-packages\django\core\handlers\base.py", line 179, in _get_response
    response = wrapped_callback(request, *callback_args, **callback_kwargs)
TypeError: login() missing 1 required positional argument: 'user'
Internal Server Error: /login/
Traceback (most recent call last):
  File "C:\Users\22520\AppData\Local\Programs\Python\Python39\lib\site-packages\django\core\handlers\exception.py", line 47, in inner
    response = get_response(request)
  File "C:\Users\22520\AppData\Local\Programs\Python\Python39\lib\site-packages\django\core\handlers\base.py", line 179, in _get_response
    response = wrapped_callback(request, *callback_args, **callback_kwargs)
TypeError: login() missing 1 required positional argument: 'user'
Internal Server Error: /login/
Traceback (most recent call last):
  File "C:\Users\22520\AppData\Local\Programs\Python\Python39\lib\site-packages\django\core\handlers\exception.py", line 47, in inner
    response = get_response(request)
  File "C:\Users\22520\AppData\Local\Programs\Python\Python39\lib\site-packages\django\core\handlers\base.py", line 179, in _get_response
    response = wrapped_callback(request, *callback_args, **callback_kwargs)
TypeError: login() missing 1 required positional argument: 'user'
Internal Server Error: /login/
Traceback (most recent call last):
  File "C:\Users\22520\AppData\Local\Programs\Python\Python39\lib\site-packages\django\core\handlers\exception.py", line 47, in inner
    response = get_response(request)
  File "C:\Users\22520\AppData\Local\Programs\Python\Python39\lib\site-packages\django\core\handlers\base.py", line 179, in _get_response
    response = wrapped_callback(request, *callback_args, **callback_kwargs)
TypeError: login() missing 1 required positional argument: 'user'
Internal Server Error: /login/
Traceback (most recent call last):
  File "C:\Users\22520\AppData\Local\Programs\Python\Python39\lib\site-packages\django\core\handlers\exception.py", line 47, in inner
    response = get_response(request)
  File "C:\Users\22520\AppData\Local\Programs\Python\Python39\lib\site-packages\django\core\handlers\base.py", line 179, in _get_response
    response = wrapped_callback(request, *callback_args, **callback_kwargs)
TypeError: login() missing 1 required positional argument: 'user'
Internal Server Error: /login/
Traceback (most recent call last):
  File "C:\Users\22520\AppData\Local\Programs\Python\Python39\lib\site-packages\django\core\handlers\exception.py", line 47, in inner
    response = get_response(request)
  File "C:\Users\22520\AppData\Local\Programs\Python\Python39\lib\site-packages\django\core\handlers\base.py", line 179, in _get_response
    response = wrapped_callback(request, *callback_args, **callback_kwargs)
TypeError: login() missing 1 required positional argument: 'user'
Internal Server Error: /login/
Traceback (most recent call last):
  File "C:\Users\22520\AppData\Local\Programs\Python\Python39\lib\site-packages\django\core\handlers\exception.py", line 47, in inner
    response = get_response(request)
  File "C:\Users\22520\AppData\Local\Programs\Python\Python39\lib\site-packages\django\core\handlers\base.py", line 179, in _get_response
    response = wrapped_callback(request, *callback_args, **callback_kwargs)
TypeError: login() missing 1 required positional argument: 'user'
Internal Server Error: /login/
Traceback (most recent call last):
  File "C:\Users\22520\AppData\Local\Programs\Python\Python39\lib\site-packages\django\core\handlers\exception.py", line 47, in inner
    response = get_response(request)
  File "C:\Users\22520\AppData\Local\Programs\Python\Python39\lib\site-packages\django\core\handlers\base.py", line 179, in _get_response
    response = wrapped_callback(request, *callback_args, **callback_kwargs)
TypeError: login() missing 1 required positional argument: 'user'
Internal Server Error: /login/
Traceback (most recent call last):
  File "C:\Users\22520\AppData\Local\Programs\Python\Python39\lib\site-packages\django\core\handlers\exception.py", line 47, in inner
    response = get_response(request)
  File "C:\Users\22520\AppData\Local\Programs\Python\Python39\lib\site-packages\django\core\handlers\base.py", line 179, in _get_response
    response = wrapped_callback(request, *callback_args, **callback_kwargs)
TypeError: login() missing 1 required positional argument: 'user'
Internal Server Error: /login/
Traceback (most recent call last):
  File "C:\Users\22520\AppData\Local\Programs\Python\Python39\lib\site-packages\django\core\handlers\exception.py", line 47, in inner
    response = get_response(request)
  File "C:\Users\22520\AppData\Local\Programs\Python\Python39\lib\site-packages\django\core\handlers\base.py", line 179, in _get_response
    response = wrapped_callback(request, *callback_args, **callback_kwargs)
TypeError: login() missing 1 required positional argument: 'user'
Internal Server Error: /login/
Traceback (most recent call last):
  File "C:\Users\22520\AppData\Local\Programs\Python\Python39\lib\site-packages\django\core\handlers\exception.py", line 47, in inner
    response = get_response(request)
  File "C:\Users\22520\AppData\Local\Programs\Python\Python39\lib\site-packages\django\core\handlers\base.py", line 179, in _get_response
    response = wrapped_callback(request, *callback_args, **callback_kwargs)
TypeError: login() missing 1 required positional argument: 'user'
Internal Server Error: /login/
Traceback (most recent call last):
  File "C:\Users\22520\AppData\Local\Programs\Python\Python39\lib\site-packages\django\core\handlers\exception.py", line 47, in inner
    response = get_response(request)
  File "C:\Users\22520\AppData\Local\Programs\Python\Python39\lib\site-packages\django\core\handlers\base.py", line 179, in _get_response
    response = wrapped_callback(request, *callback_args, **callback_kwargs)
TypeError: login() missing 1 required positional argument: 'user'
Internal Server Error: /login/
Traceback (most recent call last):
  File "C:\Users\22520\AppData\Local\Programs\Python\Python39\lib\site-packages\django\core\handlers\exception.py", line 47, in inner
    response = get_response(request)
  File "C:\Users\22520\AppData\Local\Programs\Python\Python39\lib\site-packages\django\core\handlers\base.py", line 179, in _get_response
    response = wrapped_callback(request, *callback_args, **callback_kwargs)
TypeError: login() missing 1 required positional argument: 'user'
Internal Server Error: /login/
Traceback (most recent call last):
  File "C:\Users\22520\AppData\Local\Programs\Python\Python39\lib\site-packages\django\core\handlers\exception.py", line 47, in inner
    response = get_response(request)
  File "C:\Users\22520\AppData\Local\Programs\Python\Python39\lib\site-packages\django\core\handlers\base.py", line 179, in _get_response
    response = wrapped_callback(request, *callback_args, **callback_kwargs)
TypeError: login() missing 1 required positional argument: 'user'
Internal Server Error: /login/
Traceback (most recent call last):
  File "C:\Users\22520\AppData\Local\Programs\Python\Python39\lib\site-packages\django\core\handlers\exception.py", line 47, in inner
    response = get_response(request)
  File "C:\Users\22520\AppData\Local\Programs\Python\Python39\lib\site-packages\django\core\handlers\base.py", line 179, in _get_response
    response = wrapped_callback(request, *callback_args, **callback_kwargs)
TypeError: login() missing 1 required positional argument: 'user'
Internal Server Error: /login/
Traceback (most recent call last):
  File "C:\Users\22520\AppData\Local\Programs\Python\Python39\lib\site-packages\django\core\handlers\exception.py", line 47, in inner
    response = get_response(request)
  File "C:\Users\22520\AppData\Local\Programs\Python\Python39\lib\site-packages\django\core\handlers\base.py", line 179, in _get_response
    response = wrapped_callback(request, *callback_args, **callback_kwargs)
TypeError: login() missing 1 required positional argument: 'user'
Internal Server Error: /login/
Traceback (most recent call last):
  File "C:\Users\22520\AppData\Local\Programs\Python\Python39\lib\site-packages\django\core\handlers\exception.py", line 47, in inner
    response = get_response(request)
  File "C:\Users\22520\AppData\Local\Programs\Python\Python39\lib\site-packages\django\core\handlers\base.py", line 179, in _get_response
    response = wrapped_callback(request, *callback_args, **callback_kwargs)
TypeError: login() missing 1 required positional argument: 'user'
Internal Server Error: /login/
Traceback (most recent call last):
  File "C:\Users\22520\AppData\Local\Programs\Python\Python39\lib\site-packages\django\core\handlers\exception.py", line 47, in inner
    response = get_response(request)
  File "C:\Users\22520\AppData\Local\Programs\Python\Python39\lib\site-packages\django\core\handlers\base.py", line 179, in _get_response
    response = wrapped_callback(request, *callback_args, **callback_kwargs)
TypeError: login() missing 1 required positional argument: 'user'
Internal Server Error: /login/
Traceback (most recent call last):
  File "C:\Users\22520\AppData\Local\Programs\Python\Python39\lib\site-packages\django\core\handlers\exception.py", line 47, in inner
    response = get_response(request)
  File "C:\Users\22520\AppData\Local\Programs\Python\Python39\lib\site-packages\django\core\handlers\base.py", line 179, in _get_response
    response = wrapped_callback(request, *callback_args, **callback_kwargs)
TypeError: login() missing 1 required positional argument: 'user'
Internal Server Error: /login/
Traceback (most recent call last):
  File "C:\Users\22520\AppData\Local\Programs\Python\Python39\lib\site-packages\django\core\handlers\exception.py", line 47, in inner
    response = get_response(request)
  File "C:\Users\22520\AppData\Local\Programs\Python\Python39\lib\site-packages\django\core\handlers\base.py", line 179, in _get_response
    response = wrapped_callback(request, *callback_args, **callback_kwargs)
  File "D:\text1\zhigeng_Blog\Login\views.py", line 39, in login
    return render(request, 'login/login.html', {"message": message})
  File "C:\Users\22520\AppData\Local\Programs\Python\Python39\lib\site-packages\django\shortcuts.py", line 19, in render
    content = loader.render_to_string(template_name, context, request, using=using)
  File "C:\Users\22520\AppData\Local\Programs\Python\Python39\lib\site-packages\django\template\loader.py", line 61, in render_to_string
    template = get_template(template_name, using=using)
  File "C:\Users\22520\AppData\Local\Programs\Python\Python39\lib\site-packages\django\template\loader.py", line 19, in get_template
    raise TemplateDoesNotExist(template_name, chain=chain)
django.template.exceptions.TemplateDoesNotExist: login/login.html
Internal Server Error: /login/
Traceback (most recent call last):
  File "C:\Users\22520\AppData\Local\Programs\Python\Python39\lib\site-packages\django\core\handlers\exception.py", line 47, in inner
    response = get_response(request)
  File "C:\Users\22520\AppData\Local\Programs\Python\Python39\lib\site-packages\django\core\handlers\base.py", line 179, in _get_response
    response = wrapped_callback(request, *callback_args, **callback_kwargs)
  File "D:\text1\zhigeng_Blog\Login\views.py", line 39, in login
    return render(request, 'login/login.html', {"message": message})
  File "C:\Users\22520\AppData\Local\Programs\Python\Python39\lib\site-packages\django\shortcuts.py", line 19, in render
    content = loader.render_to_string(template_name, context, request, using=using)
  File "C:\Users\22520\AppData\Local\Programs\Python\Python39\lib\site-packages\django\template\loader.py", line 61, in render_to_string
    template = get_template(template_name, using=using)
  File "C:\Users\22520\AppData\Local\Programs\Python\Python39\lib\site-packages\django\template\loader.py", line 19, in get_template
    raise TemplateDoesNotExist(template_name, chain=chain)
django.template.exceptions.TemplateDoesNotExist: login/login.html
Internal Server Error: /login/
Traceback (most recent call last):
  File "C:\Users\22520\AppData\Local\Programs\Python\Python39\lib\site-packages\django\core\handlers\exception.py", line 47, in inner
    response = get_response(request)
  File "C:\Users\22520\AppData\Local\Programs\Python\Python39\lib\site-packages\django\core\handlers\base.py", line 179, in _get_response
    response = wrapped_callback(request, *callback_args, **callback_kwargs)
  File "D:\text1\zhigeng_Blog\Login\views.py", line 39, in login
    return render(request, 'login/login.html', {"message": message})
  File "C:\Users\22520\AppData\Local\Programs\Python\Python39\lib\site-packages\django\shortcuts.py", line 19, in render
    content = loader.render_to_string(template_name, context, request, using=using)
  File "C:\Users\22520\AppData\Local\Programs\Python\Python39\lib\site-packages\django\template\loader.py", line 61, in render_to_string
    template = get_template(template_name, using=using)
  File "C:\Users\22520\AppData\Local\Programs\Python\Python39\lib\site-packages\django\template\loader.py", line 19, in get_template
    raise TemplateDoesNotExist(template_name, chain=chain)
django.template.exceptions.TemplateDoesNotExist: login/login.html
Internal Server Error: /login/
Traceback (most recent call last):
  File "C:\Users\22520\AppData\Local\Programs\Python\Python39\lib\site-packages\django\core\handlers\exception.py", line 47, in inner
    response = get_response(request)
  File "C:\Users\22520\AppData\Local\Programs\Python\Python39\lib\site-packages\django\core\handlers\base.py", line 179, in _get_response
    response = wrapped_callback(request, *callback_args, **callback_kwargs)
  File "D:\text1\zhigeng_Blog\Login\views.py", line 40, in login
    return render(request, 'login/login.html')
  File "C:\Users\22520\AppData\Local\Programs\Python\Python39\lib\site-packages\django\shortcuts.py", line 19, in render
    content = loader.render_to_string(template_name, context, request, using=using)
  File "C:\Users\22520\AppData\Local\Programs\Python\Python39\lib\site-packages\django\template\loader.py", line 61, in render_to_string
    template = get_template(template_name, using=using)
  File "C:\Users\22520\AppData\Local\Programs\Python\Python39\lib\site-packages\django\template\loader.py", line 19, in get_template
    raise TemplateDoesNotExist(template_name, chain=chain)
django.template.exceptions.TemplateDoesNotExist: login/login.html
Internal Server Error: /login/
Traceback (most recent call last):
  File "C:\Users\22520\AppData\Local\Programs\Python\Python39\lib\site-packages\django\core\handlers\exception.py", line 47, in inner
    response = get_response(request)
  File "C:\Users\22520\AppData\Local\Programs\Python\Python39\lib\site-packages\django\core\handlers\base.py", line 179, in _get_response
    response = wrapped_callback(request, *callback_args, **callback_kwargs)
  File "D:\text1\zhigeng_Blog\Login\views.py", line 40, in login
    return render(request, 'login/login.html')
  File "C:\Users\22520\AppData\Local\Programs\Python\Python39\lib\site-packages\django\shortcuts.py", line 19, in render
    content = loader.render_to_string(template_name, context, request, using=using)
  File "C:\Users\22520\AppData\Local\Programs\Python\Python39\lib\site-packages\django\template\loader.py", line 61, in render_to_string
    template = get_template(template_name, using=using)
  File "C:\Users\22520\AppData\Local\Programs\Python\Python39\lib\site-packages\django\template\loader.py", line 19, in get_template
    raise TemplateDoesNotExist(template_name, chain=chain)
django.template.exceptions.TemplateDoesNotExist: login/login.html
Internal Server Error: /login/
Traceback (most recent call last):
  File "C:\Users\22520\AppData\Local\Programs\Python\Python39\lib\site-packages\django\core\handlers\exception.py", line 47, in inner
    response = get_response(request)
  File "C:\Users\22520\AppData\Local\Programs\Python\Python39\lib\site-packages\django\core\handlers\base.py", line 179, in _get_response
    response = wrapped_callback(request, *callback_args, **callback_kwargs)
  File "D:\text1\zhigeng_Blog\Login\views.py", line 40, in login
    return render(request, 'login/login.html')
  File "C:\Users\22520\AppData\Local\Programs\Python\Python39\lib\site-packages\django\shortcuts.py", line 19, in render
    content = loader.render_to_string(template_name, context, request, using=using)
  File "C:\Users\22520\AppData\Local\Programs\Python\Python39\lib\site-packages\django\template\loader.py", line 61, in render_to_string
    template = get_template(template_name, using=using)
  File "C:\Users\22520\AppData\Local\Programs\Python\Python39\lib\site-packages\django\template\loader.py", line 19, in get_template
    raise TemplateDoesNotExist(template_name, chain=chain)
django.template.exceptions.TemplateDoesNotExist: login/login.html
Internal Server Error: /login/
Traceback (most recent call last):
  File "C:\Users\22520\AppData\Local\Programs\Python\Python39\lib\site-packages\django\core\handlers\exception.py", line 47, in inner
    response = get_response(request)
  File "C:\Users\22520\AppData\Local\Programs\Python\Python39\lib\site-packages\django\core\handlers\base.py", line 179, in _get_response
    response = wrapped_callback(request, *callback_args, **callback_kwargs)
  File "D:\text1\zhigeng_Blog\Login\views.py", line 40, in login
    return render('login.html',{'userform':userform})
  File "C:\Users\22520\AppData\Local\Programs\Python\Python39\lib\site-packages\django\shortcuts.py", line 19, in render
    content = loader.render_to_string(template_name, context, request, using=using)
  File "C:\Users\22520\AppData\Local\Programs\Python\Python39\lib\site-packages\django\template\loader.py", line 61, in render_to_string
    template = get_template(template_name, using=using)
  File "C:\Users\22520\AppData\Local\Programs\Python\Python39\lib\site-packages\django\template\loader.py", line 15, in get_template
    return engine.get_template(template_name)
  File "C:\Users\22520\AppData\Local\Programs\Python\Python39\lib\site-packages\django\template\backends\django.py", line 34, in get_template
    return Template(self.engine.get_template(template_name), self)
  File "C:\Users\22520\AppData\Local\Programs\Python\Python39\lib\site-packages\django\template\engine.py", line 143, in get_template
    template, origin = self.find_template(template_name)
  File "C:\Users\22520\AppData\Local\Programs\Python\Python39\lib\site-packages\django\template\engine.py", line 125, in find_template
    template = loader.get_template(name, skip=skip)
  File "C:\Users\22520\AppData\Local\Programs\Python\Python39\lib\site-packages\django\template\loaders\base.py", line 18, in get_template
    for origin in self.get_template_sources(template_name):
  File "C:\Users\22520\AppData\Local\Programs\Python\Python39\lib\site-packages\django\template\loaders\filesystem.py", line 36, in get_template_sources
    name = safe_join(template_dir, template_name)
  File "C:\Users\22520\AppData\Local\Programs\Python\Python39\lib\site-packages\django\utils\_os.py", line 17, in safe_join
    final_path = abspath(join(base, *paths))
  File "C:\Users\22520\AppData\Local\Programs\Python\Python39\lib\ntpath.py", line 117, in join
    genericpath._check_arg_types('join', path, *paths)
  File "C:\Users\22520\AppData\Local\Programs\Python\Python39\lib\genericpath.py", line 152, in _check_arg_types
    raise TypeError(f'{funcname}() argument must be str, bytes, or '
TypeError: join() argument must be str, bytes, or os.PathLike object, not 'dict'
Internal Server Error: /login/
Traceback (most recent call last):
  File "C:\Users\22520\AppData\Local\Programs\Python\Python39\lib\site-packages\django\core\handlers\exception.py", line 47, in inner
    response = get_response(request)
  File "C:\Users\22520\AppData\Local\Programs\Python\Python39\lib\site-packages\django\core\handlers\base.py", line 179, in _get_response
    response = wrapped_callback(request, *callback_args, **callback_kwargs)
  File "D:\text1\zhigeng_Blog\Login\views.py", line 40, in login
    return render('login.html',{'userform':userform})
  File "C:\Users\22520\AppData\Local\Programs\Python\Python39\lib\site-packages\django\shortcuts.py", line 19, in render
    content = loader.render_to_string(template_name, context, request, using=using)
  File "C:\Users\22520\AppData\Local\Programs\Python\Python39\lib\site-packages\django\template\loader.py", line 61, in render_to_string
    template = get_template(template_name, using=using)
  File "C:\Users\22520\AppData\Local\Programs\Python\Python39\lib\site-packages\django\template\loader.py", line 15, in get_template
    return engine.get_template(template_name)
  File "C:\Users\22520\AppData\Local\Programs\Python\Python39\lib\site-packages\django\template\backends\django.py", line 34, in get_template
    return Template(self.engine.get_template(template_name), self)
  File "C:\Users\22520\AppData\Local\Programs\Python\Python39\lib\site-packages\django\template\engine.py", line 143, in get_template
    template, origin = self.find_template(template_name)
  File "C:\Users\22520\AppData\Local\Programs\Python\Python39\lib\site-packages\django\template\engine.py", line 125, in find_template
    template = loader.get_template(name, skip=skip)
  File "C:\Users\22520\AppData\Local\Programs\Python\Python39\lib\site-packages\django\template\loaders\base.py", line 18, in get_template
    for origin in self.get_template_sources(template_name):
  File "C:\Users\22520\AppData\Local\Programs\Python\Python39\lib\site-packages\django\template\loaders\filesystem.py", line 36, in get_template_sources
    name = safe_join(template_dir, template_name)
  File "C:\Users\22520\AppData\Local\Programs\Python\Python39\lib\site-packages\django\utils\_os.py", line 17, in safe_join
    final_path = abspath(join(base, *paths))
  File "C:\Users\22520\AppData\Local\Programs\Python\Python39\lib\ntpath.py", line 117, in join
    genericpath._check_arg_types('join', path, *paths)
  File "C:\Users\22520\AppData\Local\Programs\Python\Python39\lib\genericpath.py", line 152, in _check_arg_types
    raise TypeError(f'{funcname}() argument must be str, bytes, or '
TypeError: join() argument must be str, bytes, or os.PathLike object, not 'dict'
Internal Server Error: /index/
Traceback (most recent call last):
  File "C:\Users\22520\AppData\Local\Programs\Python\Python39\lib\site-packages\django\core\handlers\exception.py", line 47, in inner
    response = get_response(request)
  File "C:\Users\22520\AppData\Local\Programs\Python\Python39\lib\site-packages\django\core\handlers\base.py", line 179, in _get_response
    response = wrapped_callback(request, *callback_args, **callback_kwargs)
  File "D:\text1\zhigeng_Blog\Login\views.py", line 6, in index
    return render(request, 'login/index.html')
  File "C:\Users\22520\AppData\Local\Programs\Python\Python39\lib\site-packages\django\shortcuts.py", line 19, in render
    content = loader.render_to_string(template_name, context, request, using=using)
  File "C:\Users\22520\AppData\Local\Programs\Python\Python39\lib\site-packages\django\template\loader.py", line 61, in render_to_string
    template = get_template(template_name, using=using)
  File "C:\Users\22520\AppData\Local\Programs\Python\Python39\lib\site-packages\django\template\loader.py", line 19, in get_template
    raise TemplateDoesNotExist(template_name, chain=chain)
django.template.exceptions.TemplateDoesNotExist: login/index.html
Internal Server Error: /index/
Traceback (most recent call last):
  File "C:\Users\22520\AppData\Local\Programs\Python\Python39\lib\site-packages\django\core\handlers\exception.py", line 47, in inner
    response = get_response(request)
  File "C:\Users\22520\AppData\Local\Programs\Python\Python39\lib\site-packages\django\core\handlers\base.py", line 179, in _get_response
    response = wrapped_callback(request, *callback_args, **callback_kwargs)
  File "D:\text1\zhigeng_Blog\Login\views.py", line 6, in index
    return render(request, 'login/index.html')
  File "C:\Users\22520\AppData\Local\Programs\Python\Python39\lib\site-packages\django\shortcuts.py", line 19, in render
    content = loader.render_to_string(template_name, context, request, using=using)
  File "C:\Users\22520\AppData\Local\Programs\Python\Python39\lib\site-packages\django\template\loader.py", line 61, in render_to_string
    template = get_template(template_name, using=using)
  File "C:\Users\22520\AppData\Local\Programs\Python\Python39\lib\site-packages\django\template\loader.py", line 19, in get_template
    raise TemplateDoesNotExist(template_name, chain=chain)
django.template.exceptions.TemplateDoesNotExist: login/index.html
Internal Server Error: /register/
Traceback (most recent call last):
  File "C:\Users\22520\AppData\Local\Programs\Python\Python39\lib\site-packages\django\core\handlers\exception.py", line 47, in inner
    response = get_response(request)
  File "C:\Users\22520\AppData\Local\Programs\Python\Python39\lib\site-packages\django\core\handlers\base.py", line 186, in _get_response
    self.check_response(response, callback)
  File "C:\Users\22520\AppData\Local\Programs\Python\Python39\lib\site-packages\django\core\handlers\base.py", line 307, in check_response
    raise ValueError(
ValueError: The view Login.views.register didn't return an HttpResponse object. It returned None instead.
Internal Server Error: /login/
Traceback (most recent call last):
  File "C:\Users\LENOVO\AppData\Local\Programs\Python\Python37\lib\site-packages\django\core\handlers\exception.py", line 47, in inner
    response = get_response(request)
  File "C:\Users\LENOVO\AppData\Local\Programs\Python\Python37\lib\site-packages\django\core\handlers\base.py", line 179, in _get_response
    response = wrapped_callback(request, *callback_args, **callback_kwargs)
  File "D:\Space\Pycharm_workspace\djangoProject\zhigengBlog\Login\views.py", line 33, in login
    return render(request, 'index..html', locals())
  File "C:\Users\LENOVO\AppData\Local\Programs\Python\Python37\lib\site-packages\django\shortcuts.py", line 19, in render
    content = loader.render_to_string(template_name, context, request, using=using)
  File "C:\Users\LENOVO\AppData\Local\Programs\Python\Python37\lib\site-packages\django\template\loader.py", line 61, in render_to_string
    template = get_template(template_name, using=using)
  File "C:\Users\LENOVO\AppData\Local\Programs\Python\Python37\lib\site-packages\django\template\loader.py", line 19, in get_template
    raise TemplateDoesNotExist(template_name, chain=chain)
django.template.exceptions.TemplateDoesNotExist: index..html
Internal Server Error: /
Traceback (most recent call last):
  File "E:\项目\zhigengBlog\venv\lib\site-packages\django\core\handlers\exception.py", line 47, in inner
    response = get_response(request)
  File "E:\项目\zhigengBlog\venv\lib\site-packages\django\core\handlers\base.py", line 179, in _get_response
    response = wrapped_callback(request, *callback_args, **callback_kwargs)
  File "E:\项目\zhigeng_Blog\Login\views.py", line 8, in index
    return render('index.html')
TypeError: render() missing 1 required positional argument: 'template_name'
Internal Server Error: /tologin/
Traceback (most recent call last):
  File "E:\项目\zhigengBlog\venv\lib\site-packages\django\core\handlers\exception.py", line 47, in inner
    response = get_response(request)
  File "E:\项目\zhigengBlog\venv\lib\site-packages\django\core\handlers\base.py", line 179, in _get_response
    response = wrapped_callback(request, *callback_args, **callback_kwargs)
  File "E:\项目\zhigeng_Blog\Login\views.py", line 12, in tologin
    return render('login.html')
TypeError: render() missing 1 required positional argument: 'template_name'
Internal Server Error: /login/
Traceback (most recent call last):
  File "E:\项目\zhigengBlog\venv\lib\site-packages\django\core\handlers\exception.py", line 47, in inner
    response = get_response(request)
  File "E:\项目\zhigengBlog\venv\lib\site-packages\django\core\handlers\base.py", line 186, in _get_response
    self.check_response(response, callback)
  File "E:\项目\zhigengBlog\venv\lib\site-packages\django\core\handlers\base.py", line 309, in check_response
    "instead." % name
ValueError: The view Login.views.login didn't return an HttpResponse object. It returned None instead.
Internal Server Error: /login/
Traceback (most recent call last):
  File "E:\项目\zhigengBlog\venv\lib\site-packages\django\core\handlers\exception.py", line 47, in inner
    response = get_response(request)
  File "E:\项目\zhigengBlog\venv\lib\site-packages\django\core\handlers\base.py", line 179, in _get_response
    response = wrapped_callback(request, *callback_args, **callback_kwargs)
  File "E:\项目\zhigeng_Blog\Login\views.py", line 23, in login
    {'err': 0}
TypeError: unhashable type: 'dict'
Internal Server Error: /login/
Traceback (most recent call last):
  File "E:\项目\zhigengBlog\venv\lib\site-packages\django\core\handlers\exception.py", line 47, in inner
    response = get_response(request)
  File "E:\项目\zhigengBlog\venv\lib\site-packages\django\core\handlers\base.py", line 186, in _get_response
    self.check_response(response, callback)
  File "E:\项目\zhigengBlog\venv\lib\site-packages\django\core\handlers\base.py", line 309, in check_response
    "instead." % name
ValueError: The view Login.views.login didn't return an HttpResponse object. It returned None instead.
Internal Server Error: /login/
Traceback (most recent call last):
  File "E:\项目\zhigengBlog\venv\lib\site-packages\django\template\base.py", line 470, in parse
    compile_func = self.tags[command]
KeyError: 'err'

During handling of the above exception, another exception occurred:

Traceback (most recent call last):
  File "E:\项目\zhigengBlog\venv\lib\site-packages\django\core\handlers\exception.py", line 47, in inner
    response = get_response(request)
  File "E:\项目\zhigengBlog\venv\lib\site-packages\django\core\handlers\base.py", line 179, in _get_response
    response = wrapped_callback(request, *callback_args, **callback_kwargs)
  File "E:\项目\zhigeng_Blog\Login\views.py", line 47, in login
    return render(request, 'login.html', context)
  File "E:\项目\zhigengBlog\venv\lib\site-packages\django\shortcuts.py", line 19, in render
    content = loader.render_to_string(template_name, context, request, using=using)
  File "E:\项目\zhigengBlog\venv\lib\site-packages\django\template\loader.py", line 61, in render_to_string
    template = get_template(template_name, using=using)
  File "E:\项目\zhigengBlog\venv\lib\site-packages\django\template\loader.py", line 15, in get_template
    return engine.get_template(template_name)
  File "E:\项目\zhigengBlog\venv\lib\site-packages\django\template\backends\django.py", line 34, in get_template
    return Template(self.engine.get_template(template_name), self)
  File "E:\项目\zhigengBlog\venv\lib\site-packages\django\template\engine.py", line 143, in get_template
    template, origin = self.find_template(template_name)
  File "E:\项目\zhigengBlog\venv\lib\site-packages\django\template\engine.py", line 125, in find_template
    template = loader.get_template(name, skip=skip)
  File "E:\项目\zhigengBlog\venv\lib\site-packages\django\template\loaders\base.py", line 30, in get_template
    contents, origin, origin.template_name, self.engine,
  File "E:\项目\zhigengBlog\venv\lib\site-packages\django\template\base.py", line 155, in __init__
    self.nodelist = self.compile_nodelist()
  File "E:\项目\zhigengBlog\venv\lib\site-packages\django\template\base.py", line 193, in compile_nodelist
    return parser.parse()
  File "E:\项目\zhigengBlog\venv\lib\site-packages\django\template\base.py", line 472, in parse
    self.invalid_block_tag(token, command, parse_until)
  File "E:\项目\zhigengBlog\venv\lib\site-packages\django\template\base.py", line 534, in invalid_block_tag
    "or load this tag?" % (token.lineno, command)
django.template.exceptions.TemplateSyntaxError: Invalid block tag on line 113: 'err'. Did you forget to register or load this tag?
Internal Server Error: /login/
Traceback (most recent call last):
  File "E:\项目\zhigengBlog\venv\lib\site-packages\django\template\base.py", line 470, in parse
    compile_func = self.tags[command]
KeyError: 'err'

During handling of the above exception, another exception occurred:

Traceback (most recent call last):
  File "E:\项目\zhigengBlog\venv\lib\site-packages\django\core\handlers\exception.py", line 47, in inner
    response = get_response(request)
  File "E:\项目\zhigengBlog\venv\lib\site-packages\django\core\handlers\base.py", line 179, in _get_response
    response = wrapped_callback(request, *callback_args, **callback_kwargs)
  File "E:\项目\zhigeng_Blog\Login\views.py", line 47, in login
    return render(request, 'login.html', context)
  File "E:\项目\zhigengBlog\venv\lib\site-packages\django\shortcuts.py", line 19, in render
    content = loader.render_to_string(template_name, context, request, using=using)
  File "E:\项目\zhigengBlog\venv\lib\site-packages\django\template\loader.py", line 61, in render_to_string
    template = get_template(template_name, using=using)
  File "E:\项目\zhigengBlog\venv\lib\site-packages\django\template\loader.py", line 15, in get_template
    return engine.get_template(template_name)
  File "E:\项目\zhigengBlog\venv\lib\site-packages\django\template\backends\django.py", line 34, in get_template
    return Template(self.engine.get_template(template_name), self)
  File "E:\项目\zhigengBlog\venv\lib\site-packages\django\template\engine.py", line 143, in get_template
    template, origin = self.find_template(template_name)
  File "E:\项目\zhigengBlog\venv\lib\site-packages\django\template\engine.py", line 125, in find_template
    template = loader.get_template(name, skip=skip)
  File "E:\项目\zhigengBlog\venv\lib\site-packages\django\template\loaders\base.py", line 30, in get_template
    contents, origin, origin.template_name, self.engine,
  File "E:\项目\zhigengBlog\venv\lib\site-packages\django\template\base.py", line 155, in __init__
    self.nodelist = self.compile_nodelist()
  File "E:\项目\zhigengBlog\venv\lib\site-packages\django\template\base.py", line 193, in compile_nodelist
    return parser.parse()
  File "E:\项目\zhigengBlog\venv\lib\site-packages\django\template\base.py", line 472, in parse
    self.invalid_block_tag(token, command, parse_until)
  File "E:\项目\zhigengBlog\venv\lib\site-packages\django\template\base.py", line 534, in invalid_block_tag
    "or load this tag?" % (token.lineno, command)
django.template.exceptions.TemplateSyntaxError: Invalid block tag on line 113: 'err'. Did you forget to register or load this tag?
Internal Server Error: /login/
Traceback (most recent call last):
  File "E:\项目\zhigengBlog\venv\lib\site-packages\django\template\base.py", line 470, in parse
    compile_func = self.tags[command]
KeyError: 'err'

During handling of the above exception, another exception occurred:

Traceback (most recent call last):
  File "E:\项目\zhigengBlog\venv\lib\site-packages\django\core\handlers\exception.py", line 47, in inner
    response = get_response(request)
  File "E:\项目\zhigengBlog\venv\lib\site-packages\django\core\handlers\base.py", line 179, in _get_response
    response = wrapped_callback(request, *callback_args, **callback_kwargs)
  File "E:\项目\zhigeng_Blog\Login\views.py", line 47, in login
    return render(request, 'login.html', context)
  File "E:\项目\zhigengBlog\venv\lib\site-packages\django\shortcuts.py", line 19, in render
    content = loader.render_to_string(template_name, context, request, using=using)
  File "E:\项目\zhigengBlog\venv\lib\site-packages\django\template\loader.py", line 61, in render_to_string
    template = get_template(template_name, using=using)
  File "E:\项目\zhigengBlog\venv\lib\site-packages\django\template\loader.py", line 15, in get_template
    return engine.get_template(template_name)
  File "E:\项目\zhigengBlog\venv\lib\site-packages\django\template\backends\django.py", line 34, in get_template
    return Template(self.engine.get_template(template_name), self)
  File "E:\项目\zhigengBlog\venv\lib\site-packages\django\template\engine.py", line 143, in get_template
    template, origin = self.find_template(template_name)
  File "E:\项目\zhigengBlog\venv\lib\site-packages\django\template\engine.py", line 125, in find_template
    template = loader.get_template(name, skip=skip)
  File "E:\项目\zhigengBlog\venv\lib\site-packages\django\template\loaders\base.py", line 30, in get_template
    contents, origin, origin.template_name, self.engine,
  File "E:\项目\zhigengBlog\venv\lib\site-packages\django\template\base.py", line 155, in __init__
    self.nodelist = self.compile_nodelist()
  File "E:\项目\zhigengBlog\venv\lib\site-packages\django\template\base.py", line 193, in compile_nodelist
    return parser.parse()
  File "E:\项目\zhigengBlog\venv\lib\site-packages\django\template\base.py", line 472, in parse
    self.invalid_block_tag(token, command, parse_until)
  File "E:\项目\zhigengBlog\venv\lib\site-packages\django\template\base.py", line 534, in invalid_block_tag
    "or load this tag?" % (token.lineno, command)
django.template.exceptions.TemplateSyntaxError: Invalid block tag on line 113: 'err'. Did you forget to register or load this tag?
Internal Server Error: /login/
Traceback (most recent call last):
  File "E:\项目\zhigengBlog\venv\lib\site-packages\django\template\base.py", line 470, in parse
    compile_func = self.tags[command]
KeyError: 'message'

During handling of the above exception, another exception occurred:

Traceback (most recent call last):
  File "E:\项目\zhigengBlog\venv\lib\site-packages\django\core\handlers\exception.py", line 47, in inner
    response = get_response(request)
  File "E:\项目\zhigengBlog\venv\lib\site-packages\django\core\handlers\base.py", line 179, in _get_response
    response = wrapped_callback(request, *callback_args, **callback_kwargs)
  File "E:\项目\zhigeng_Blog\Login\views.py", line 43, in login
    return render(request, 'login.html', {'message': message})
  File "E:\项目\zhigengBlog\venv\lib\site-packages\django\shortcuts.py", line 19, in render
    content = loader.render_to_string(template_name, context, request, using=using)
  File "E:\项目\zhigengBlog\venv\lib\site-packages\django\template\loader.py", line 61, in render_to_string
    template = get_template(template_name, using=using)
  File "E:\项目\zhigengBlog\venv\lib\site-packages\django\template\loader.py", line 15, in get_template
    return engine.get_template(template_name)
  File "E:\项目\zhigengBlog\venv\lib\site-packages\django\template\backends\django.py", line 34, in get_template
    return Template(self.engine.get_template(template_name), self)
  File "E:\项目\zhigengBlog\venv\lib\site-packages\django\template\engine.py", line 143, in get_template
    template, origin = self.find_template(template_name)
  File "E:\项目\zhigengBlog\venv\lib\site-packages\django\template\engine.py", line 125, in find_template
    template = loader.get_template(name, skip=skip)
  File "E:\项目\zhigengBlog\venv\lib\site-packages\django\template\loaders\base.py", line 30, in get_template
    contents, origin, origin.template_name, self.engine,
  File "E:\项目\zhigengBlog\venv\lib\site-packages\django\template\base.py", line 155, in __init__
    self.nodelist = self.compile_nodelist()
  File "E:\项目\zhigengBlog\venv\lib\site-packages\django\template\base.py", line 193, in compile_nodelist
    return parser.parse()
  File "E:\项目\zhigengBlog\venv\lib\site-packages\django\template\base.py", line 472, in parse
    self.invalid_block_tag(token, command, parse_until)
  File "E:\项目\zhigengBlog\venv\lib\site-packages\django\template\base.py", line 534, in invalid_block_tag
    "or load this tag?" % (token.lineno, command)
django.template.exceptions.TemplateSyntaxError: Invalid block tag on line 70: 'message'. Did you forget to register or load this tag?
Internal Server Error: /tologin/
Traceback (most recent call last):
  File "E:\项目\zhigengBlog\venv\lib\site-packages\django\template\base.py", line 470, in parse
    compile_func = self.tags[command]
KeyError: 'message'

During handling of the above exception, another exception occurred:

Traceback (most recent call last):
  File "E:\项目\zhigengBlog\venv\lib\site-packages\django\core\handlers\exception.py", line 47, in inner
    response = get_response(request)
  File "E:\项目\zhigengBlog\venv\lib\site-packages\django\core\handlers\base.py", line 179, in _get_response
    response = wrapped_callback(request, *callback_args, **callback_kwargs)
  File "E:\项目\zhigeng_Blog\Login\views.py", line 14, in tologin
    return render(request, 'login.html')
  File "E:\项目\zhigengBlog\venv\lib\site-packages\django\shortcuts.py", line 19, in render
    content = loader.render_to_string(template_name, context, request, using=using)
  File "E:\项目\zhigengBlog\venv\lib\site-packages\django\template\loader.py", line 61, in render_to_string
    template = get_template(template_name, using=using)
  File "E:\项目\zhigengBlog\venv\lib\site-packages\django\template\loader.py", line 15, in get_template
    return engine.get_template(template_name)
  File "E:\项目\zhigengBlog\venv\lib\site-packages\django\template\backends\django.py", line 34, in get_template
    return Template(self.engine.get_template(template_name), self)
  File "E:\项目\zhigengBlog\venv\lib\site-packages\django\template\engine.py", line 143, in get_template
    template, origin = self.find_template(template_name)
  File "E:\项目\zhigengBlog\venv\lib\site-packages\django\template\engine.py", line 125, in find_template
    template = loader.get_template(name, skip=skip)
  File "E:\项目\zhigengBlog\venv\lib\site-packages\django\template\loaders\base.py", line 30, in get_template
    contents, origin, origin.template_name, self.engine,
  File "E:\项目\zhigengBlog\venv\lib\site-packages\django\template\base.py", line 155, in __init__
    self.nodelist = self.compile_nodelist()
  File "E:\项目\zhigengBlog\venv\lib\site-packages\django\template\base.py", line 193, in compile_nodelist
    return parser.parse()
  File "E:\项目\zhigengBlog\venv\lib\site-packages\django\template\base.py", line 472, in parse
    self.invalid_block_tag(token, command, parse_until)
  File "E:\项目\zhigengBlog\venv\lib\site-packages\django\template\base.py", line 534, in invalid_block_tag
    "or load this tag?" % (token.lineno, command)
django.template.exceptions.TemplateSyntaxError: Invalid block tag on line 70: 'message'. Did you forget to register or load this tag?
Internal Server Error: /login/
Traceback (most recent call last):
  File "E:\项目\zhigengBlog\venv\lib\site-packages\django\core\handlers\exception.py", line 47, in inner
    response = get_response(request)
  File "E:\项目\zhigengBlog\venv\lib\site-packages\django\core\handlers\base.py", line 179, in _get_response
    response = wrapped_callback(request, *callback_args, **callback_kwargs)
  File "E:\项目\zhigeng_Blog\Login\views.py", line 35, in login
    user = User.objects.get(name=username)
  File "E:\项目\zhigengBlog\venv\lib\site-packages\django\db\models\manager.py", line 85, in manager_method
    return getattr(self.get_queryset(), name)(*args, **kwargs)
  File "E:\项目\zhigengBlog\venv\lib\site-packages\django\db\models\query.py", line 431, in get
    self.model._meta.object_name
user.models.User.DoesNotExist: User matching query does not exist.
Internal Server Error: /login/
Traceback (most recent call last):
  File "E:\项目\zhigengBlog\venv\lib\site-packages\django\core\handlers\exception.py", line 47, in inner
    response = get_response(request)
  File "E:\项目\zhigengBlog\venv\lib\site-packages\django\core\handlers\base.py", line 179, in _get_response
    response = wrapped_callback(request, *callback_args, **callback_kwargs)
  File "E:\项目\zhigeng_Blog\Login\views.py", line 42, in login
    return render(request, 'login.html', {'message', message})
  File "E:\项目\zhigengBlog\venv\lib\site-packages\django\shortcuts.py", line 19, in render
    content = loader.render_to_string(template_name, context, request, using=using)
  File "E:\项目\zhigengBlog\venv\lib\site-packages\django\template\loader.py", line 62, in render_to_string
    return template.render(context, request)
  File "E:\项目\zhigengBlog\venv\lib\site-packages\django\template\backends\django.py", line 59, in render
    context = make_context(context, request, autoescape=self.backend.engine.autoescape)
  File "E:\项目\zhigengBlog\venv\lib\site-packages\django\template\context.py", line 268, in make_context
    raise TypeError('context must be a dict rather than %s.' % context.__class__.__name__)
TypeError: context must be a dict rather than set.
Internal Server Error: /login/
Traceback (most recent call last):
  File "E:\项目\zhigengBlog\venv\lib\site-packages\django\core\handlers\exception.py", line 47, in inner
    response = get_response(request)
  File "E:\项目\zhigengBlog\venv\lib\site-packages\django\core\handlers\base.py", line 179, in _get_response
    response = wrapped_callback(request, *callback_args, **callback_kwargs)
  File "E:\项目\zhigeng_Blog\Login\views.py", line 42, in login
    return render(request, 'login.html', {'message', message})
  File "E:\项目\zhigengBlog\venv\lib\site-packages\django\shortcuts.py", line 19, in render
    content = loader.render_to_string(template_name, context, request, using=using)
  File "E:\项目\zhigengBlog\venv\lib\site-packages\django\template\loader.py", line 62, in render_to_string
    return template.render(context, request)
  File "E:\项目\zhigengBlog\venv\lib\site-packages\django\template\backends\django.py", line 59, in render
    context = make_context(context, request, autoescape=self.backend.engine.autoescape)
  File "E:\项目\zhigengBlog\venv\lib\site-packages\django\template\context.py", line 268, in make_context
    raise TypeError('context must be a dict rather than %s.' % context.__class__.__name__)
TypeError: context must be a dict rather than set.
Internal Server Error: /login/
Traceback (most recent call last):
  File "E:\项目\zhigengBlog\venv\lib\site-packages\django\core\handlers\exception.py", line 47, in inner
    response = get_response(request)
  File "E:\项目\zhigengBlog\venv\lib\site-packages\django\core\handlers\base.py", line 179, in _get_response
    response = wrapped_callback(request, *callback_args, **callback_kwargs)
  File "E:\项目\zhigeng_Blog\Login\views.py", line 42, in login
    return render(request, 'login.html', {'message', message})
  File "E:\项目\zhigengBlog\venv\lib\site-packages\django\shortcuts.py", line 19, in render
    content = loader.render_to_string(template_name, context, request, using=using)
  File "E:\项目\zhigengBlog\venv\lib\site-packages\django\template\loader.py", line 62, in render_to_string
    return template.render(context, request)
  File "E:\项目\zhigengBlog\venv\lib\site-packages\django\template\backends\django.py", line 59, in render
    context = make_context(context, request, autoescape=self.backend.engine.autoescape)
  File "E:\项目\zhigengBlog\venv\lib\site-packages\django\template\context.py", line 268, in make_context
    raise TypeError('context must be a dict rather than %s.' % context.__class__.__name__)
TypeError: context must be a dict rather than set.
Internal Server Error: /login/
Traceback (most recent call last):
  File "E:\项目\zhigengBlog\venv\lib\site-packages\django\core\handlers\exception.py", line 47, in inner
    response = get_response(request)
  File "E:\项目\zhigengBlog\venv\lib\site-packages\django\core\handlers\base.py", line 179, in _get_response
    response = wrapped_callback(request, *callback_args, **callback_kwargs)
  File "E:\项目\zhigeng_Blog\Login\views.py", line 42, in login
    return render(request, 'login.html', {'message', message})
  File "E:\项目\zhigengBlog\venv\lib\site-packages\django\shortcuts.py", line 19, in render
    content = loader.render_to_string(template_name, context, request, using=using)
  File "E:\项目\zhigengBlog\venv\lib\site-packages\django\template\loader.py", line 62, in render_to_string
    return template.render(context, request)
  File "E:\项目\zhigengBlog\venv\lib\site-packages\django\template\backends\django.py", line 59, in render
    context = make_context(context, request, autoescape=self.backend.engine.autoescape)
  File "E:\项目\zhigengBlog\venv\lib\site-packages\django\template\context.py", line 268, in make_context
    raise TypeError('context must be a dict rather than %s.' % context.__class__.__name__)
TypeError: context must be a dict rather than set.
Internal Server Error: /login/
Traceback (most recent call last):
  File "E:\项目\zhigengBlog\venv\lib\site-packages\django\core\handlers\exception.py", line 47, in inner
    response = get_response(request)
  File "E:\项目\zhigengBlog\venv\lib\site-packages\django\core\handlers\base.py", line 186, in _get_response
    self.check_response(response, callback)
  File "E:\项目\zhigengBlog\venv\lib\site-packages\django\core\handlers\base.py", line 309, in check_response
    "instead." % name
ValueError: The view Login.views.login didn't return an HttpResponse object. It returned None instead.
Internal Server Error: /login/
Traceback (most recent call last):
  File "E:\项目\zhigengBlog\venv\lib\site-packages\django\core\handlers\exception.py", line 47, in inner
    response = get_response(request)
  File "E:\项目\zhigengBlog\venv\lib\site-packages\django\core\handlers\base.py", line 179, in _get_response
    response = wrapped_callback(request, *callback_args, **callback_kwargs)
  File "E:\项目\zhigeng_Blog\Login\views.py", line 42, in login
    return render(request, 'login.html', {'message', message})
  File "E:\项目\zhigengBlog\venv\lib\site-packages\django\shortcuts.py", line 19, in render
    content = loader.render_to_string(template_name, context, request, using=using)
  File "E:\项目\zhigengBlog\venv\lib\site-packages\django\template\loader.py", line 62, in render_to_string
    return template.render(context, request)
  File "E:\项目\zhigengBlog\venv\lib\site-packages\django\template\backends\django.py", line 59, in render
    context = make_context(context, request, autoescape=self.backend.engine.autoescape)
  File "E:\项目\zhigengBlog\venv\lib\site-packages\django\template\context.py", line 268, in make_context
    raise TypeError('context must be a dict rather than %s.' % context.__class__.__name__)
TypeError: context must be a dict rather than set.
Internal Server Error: /login/
Traceback (most recent call last):
  File "E:\项目\zhigengBlog\venv\lib\site-packages\django\core\handlers\exception.py", line 47, in inner
    response = get_response(request)
  File "E:\项目\zhigengBlog\venv\lib\site-packages\django\core\handlers\base.py", line 179, in _get_response
    response = wrapped_callback(request, *callback_args, **callback_kwargs)
  File "E:\项目\zhigeng_Blog\Login\views.py", line 42, in login
    return render(request, 'login.html', {'message', message})
  File "E:\项目\zhigengBlog\venv\lib\site-packages\django\shortcuts.py", line 19, in render
    content = loader.render_to_string(template_name, context, request, using=using)
  File "E:\项目\zhigengBlog\venv\lib\site-packages\django\template\loader.py", line 62, in render_to_string
    return template.render(context, request)
  File "E:\项目\zhigengBlog\venv\lib\site-packages\django\template\backends\django.py", line 59, in render
    context = make_context(context, request, autoescape=self.backend.engine.autoescape)
  File "E:\项目\zhigengBlog\venv\lib\site-packages\django\template\context.py", line 268, in make_context
    raise TypeError('context must be a dict rather than %s.' % context.__class__.__name__)
TypeError: context must be a dict rather than set.
Internal Server Error: /login/
Traceback (most recent call last):
  File "E:\项目\zhigengBlog\venv\lib\site-packages\django\core\handlers\exception.py", line 47, in inner
    response = get_response(request)
  File "E:\项目\zhigengBlog\venv\lib\site-packages\django\core\handlers\base.py", line 179, in _get_response
    response = wrapped_callback(request, *callback_args, **callback_kwargs)
  File "E:\项目\zhigeng_Blog\Login\views.py", line 42, in login
    return render(request, 'login.html', {'message', message})
  File "E:\项目\zhigengBlog\venv\lib\site-packages\django\shortcuts.py", line 19, in render
    content = loader.render_to_string(template_name, context, request, using=using)
  File "E:\项目\zhigengBlog\venv\lib\site-packages\django\template\loader.py", line 62, in render_to_string
    return template.render(context, request)
  File "E:\项目\zhigengBlog\venv\lib\site-packages\django\template\backends\django.py", line 59, in render
    context = make_context(context, request, autoescape=self.backend.engine.autoescape)
  File "E:\项目\zhigengBlog\venv\lib\site-packages\django\template\context.py", line 268, in make_context
    raise TypeError('context must be a dict rather than %s.' % context.__class__.__name__)
TypeError: context must be a dict rather than set.
Internal Server Error: /login/
Traceback (most recent call last):
  File "E:\项目\zhigengBlog\venv\lib\site-packages\django\core\handlers\exception.py", line 47, in inner
    response = get_response(request)
  File "E:\项目\zhigengBlog\venv\lib\site-packages\django\core\handlers\base.py", line 179, in _get_response
    response = wrapped_callback(request, *callback_args, **callback_kwargs)
  File "E:\项目\zhigeng_Blog\Login\views.py", line 42, in login
    return render(request, 'login.html', {'message', message})
  File "E:\项目\zhigengBlog\venv\lib\site-packages\django\shortcuts.py", line 19, in render
    content = loader.render_to_string(template_name, context, request, using=using)
  File "E:\项目\zhigengBlog\venv\lib\site-packages\django\template\loader.py", line 62, in render_to_string
    return template.render(context, request)
  File "E:\项目\zhigengBlog\venv\lib\site-packages\django\template\backends\django.py", line 59, in render
    context = make_context(context, request, autoescape=self.backend.engine.autoescape)
  File "E:\项目\zhigengBlog\venv\lib\site-packages\django\template\context.py", line 268, in make_context
    raise TypeError('context must be a dict rather than %s.' % context.__class__.__name__)
TypeError: context must be a dict rather than set.
Internal Server Error: /login/
Traceback (most recent call last):
  File "E:\项目\zhigengBlog\venv\lib\site-packages\django\core\handlers\exception.py", line 47, in inner
    response = get_response(request)
  File "E:\项目\zhigengBlog\venv\lib\site-packages\django\core\handlers\base.py", line 179, in _get_response
    response = wrapped_callback(request, *callback_args, **callback_kwargs)
  File "E:\项目\zhigeng_Blog\Login\views.py", line 42, in login
    return render(request, 'login.html', {'message', message})
  File "E:\项目\zhigengBlog\venv\lib\site-packages\django\shortcuts.py", line 19, in render
    content = loader.render_to_string(template_name, context, request, using=using)
  File "E:\项目\zhigengBlog\venv\lib\site-packages\django\template\loader.py", line 62, in render_to_string
    return template.render(context, request)
  File "E:\项目\zhigengBlog\venv\lib\site-packages\django\template\backends\django.py", line 59, in render
    context = make_context(context, request, autoescape=self.backend.engine.autoescape)
  File "E:\项目\zhigengBlog\venv\lib\site-packages\django\template\context.py", line 268, in make_context
    raise TypeError('context must be a dict rather than %s.' % context.__class__.__name__)
TypeError: context must be a dict rather than set.
Internal Server Error: /login/
Traceback (most recent call last):
  File "E:\项目\zhigengBlog\venv\lib\site-packages\django\core\handlers\exception.py", line 47, in inner
    response = get_response(request)
  File "E:\项目\zhigengBlog\venv\lib\site-packages\django\core\handlers\base.py", line 179, in _get_response
    response = wrapped_callback(request, *callback_args, **callback_kwargs)
  File "E:\项目\zhigeng_Blog\Login\views.py", line 42, in login
    return render(request, 'login.html', {'message', message})
  File "E:\项目\zhigengBlog\venv\lib\site-packages\django\shortcuts.py", line 19, in render
    content = loader.render_to_string(template_name, context, request, using=using)
  File "E:\项目\zhigengBlog\venv\lib\site-packages\django\template\loader.py", line 62, in render_to_string
    return template.render(context, request)
  File "E:\项目\zhigengBlog\venv\lib\site-packages\django\template\backends\django.py", line 59, in render
    context = make_context(context, request, autoescape=self.backend.engine.autoescape)
  File "E:\项目\zhigengBlog\venv\lib\site-packages\django\template\context.py", line 268, in make_context
    raise TypeError('context must be a dict rather than %s.' % context.__class__.__name__)
TypeError: context must be a dict rather than set.
Internal Server Error: /login/
Traceback (most recent call last):
  File "E:\项目\zhigengBlog\venv\lib\site-packages\django\core\handlers\exception.py", line 47, in inner
    response = get_response(request)
  File "E:\项目\zhigengBlog\venv\lib\site-packages\django\core\handlers\base.py", line 186, in _get_response
    self.check_response(response, callback)
  File "E:\项目\zhigengBlog\venv\lib\site-packages\django\core\handlers\base.py", line 309, in check_response
    "instead." % name
ValueError: The view Login.views.login didn't return an HttpResponse object. It returned None instead.
Internal Server Error: /login/
Traceback (most recent call last):
  File "E:\项目\zhigengBlog\venv\lib\site-packages\django\core\handlers\exception.py", line 47, in inner
    response = get_response(request)
  File "E:\项目\zhigengBlog\venv\lib\site-packages\django\core\handlers\base.py", line 186, in _get_response
    self.check_response(response, callback)
  File "E:\项目\zhigengBlog\venv\lib\site-packages\django\core\handlers\base.py", line 309, in check_response
    "instead." % name
ValueError: The view Login.views.login didn't return an HttpResponse object. It returned None instead.
Internal Server Error: /login/
Traceback (most recent call last):
  File "E:\项目\zhigengBlog\venv\lib\site-packages\django\core\handlers\exception.py", line 47, in inner
    response = get_response(request)
  File "E:\项目\zhigengBlog\venv\lib\site-packages\django\core\handlers\base.py", line 179, in _get_response
    response = wrapped_callback(request, *callback_args, **callback_kwargs)
  File "E:\项目\zhigeng_Blog\Login\views.py", line 45, in login
    return render(request, 'login.html', {'message', message})
  File "E:\项目\zhigengBlog\venv\lib\site-packages\django\shortcuts.py", line 19, in render
    content = loader.render_to_string(template_name, context, request, using=using)
  File "E:\项目\zhigengBlog\venv\lib\site-packages\django\template\loader.py", line 62, in render_to_string
    return template.render(context, request)
  File "E:\项目\zhigengBlog\venv\lib\site-packages\django\template\backends\django.py", line 59, in render
    context = make_context(context, request, autoescape=self.backend.engine.autoescape)
  File "E:\项目\zhigengBlog\venv\lib\site-packages\django\template\context.py", line 268, in make_context
    raise TypeError('context must be a dict rather than %s.' % context.__class__.__name__)
TypeError: context must be a dict rather than set.
Internal Server Error: /login/
Traceback (most recent call last):
  File "E:\项目\zhigengBlog\venv\lib\site-packages\django\core\handlers\exception.py", line 47, in inner
    response = get_response(request)
  File "E:\项目\zhigengBlog\venv\lib\site-packages\django\core\handlers\base.py", line 179, in _get_response
    response = wrapped_callback(request, *callback_args, **callback_kwargs)
  File "E:\项目\zhigeng_Blog\Login\views.py", line 34, in login
    user = User.objects.get(name=username)
  File "E:\项目\zhigengBlog\venv\lib\site-packages\django\db\models\manager.py", line 85, in manager_method
    return getattr(self.get_queryset(), name)(*args, **kwargs)
  File "E:\项目\zhigengBlog\venv\lib\site-packages\django\db\models\query.py", line 431, in get
    self.model._meta.object_name
user.models.User.DoesNotExist: User matching query does not exist.
Internal Server Error: /login/
Traceback (most recent call last):
  File "E:\项目\zhigengBlog\venv\lib\site-packages\django\core\handlers\exception.py", line 47, in inner
    response = get_response(request)
  File "E:\项目\zhigengBlog\venv\lib\site-packages\django\core\handlers\base.py", line 186, in _get_response
    self.check_response(response, callback)
  File "E:\项目\zhigengBlog\venv\lib\site-packages\django\core\handlers\base.py", line 309, in check_response
    "instead." % name
ValueError: The view Login.views.login didn't return an HttpResponse object. It returned None instead.
Internal Server Error: /login/
Traceback (most recent call last):
  File "E:\项目\zhigeng_Blog\Login\views.py", line 35, in login
    user = User.objects.get(name=username)
  File "E:\项目\zhigengBlog\venv\lib\site-packages\django\db\models\manager.py", line 85, in manager_method
    return getattr(self.get_queryset(), name)(*args, **kwargs)
  File "E:\项目\zhigengBlog\venv\lib\site-packages\django\db\models\query.py", line 431, in get
    self.model._meta.object_name
user.models.User.DoesNotExist: User matching query does not exist.

During handling of the above exception, another exception occurred:

Traceback (most recent call last):
  File "E:\项目\zhigengBlog\venv\lib\site-packages\django\core\handlers\exception.py", line 47, in inner
    response = get_response(request)
  File "E:\项目\zhigengBlog\venv\lib\site-packages\django\core\handlers\base.py", line 179, in _get_response
    response = wrapped_callback(request, *callback_args, **callback_kwargs)
  File "E:\项目\zhigeng_Blog\Login\views.py", line 47, in login
    return render(request, 'login.html', message)
  File "E:\项目\zhigengBlog\venv\lib\site-packages\django\shortcuts.py", line 19, in render
    content = loader.render_to_string(template_name, context, request, using=using)
  File "E:\项目\zhigengBlog\venv\lib\site-packages\django\template\loader.py", line 62, in render_to_string
    return template.render(context, request)
  File "E:\项目\zhigengBlog\venv\lib\site-packages\django\template\backends\django.py", line 59, in render
    context = make_context(context, request, autoescape=self.backend.engine.autoescape)
  File "E:\项目\zhigengBlog\venv\lib\site-packages\django\template\context.py", line 268, in make_context
    raise TypeError('context must be a dict rather than %s.' % context.__class__.__name__)
TypeError: context must be a dict rather than str.
Internal Server Error: /login/
Traceback (most recent call last):
  File "E:\项目\zhigeng_Blog\Login\views.py", line 35, in login
    user = User.objects.get(name=username)
  File "E:\项目\zhigengBlog\venv\lib\site-packages\django\db\models\manager.py", line 85, in manager_method
    return getattr(self.get_queryset(), name)(*args, **kwargs)
  File "E:\项目\zhigengBlog\venv\lib\site-packages\django\db\models\query.py", line 431, in get
    self.model._meta.object_name
user.models.User.DoesNotExist: User matching query does not exist.

During handling of the above exception, another exception occurred:

Traceback (most recent call last):
  File "E:\项目\zhigengBlog\venv\lib\site-packages\django\core\handlers\exception.py", line 47, in inner
    response = get_response(request)
  File "E:\项目\zhigengBlog\venv\lib\site-packages\django\core\handlers\base.py", line 179, in _get_response
    response = wrapped_callback(request, *callback_args, **callback_kwargs)
  File "E:\项目\zhigeng_Blog\Login\views.py", line 47, in login
    return render(request, 'login.html', message)
  File "E:\项目\zhigengBlog\venv\lib\site-packages\django\shortcuts.py", line 19, in render
    content = loader.render_to_string(template_name, context, request, using=using)
  File "E:\项目\zhigengBlog\venv\lib\site-packages\django\template\loader.py", line 62, in render_to_string
    return template.render(context, request)
  File "E:\项目\zhigengBlog\venv\lib\site-packages\django\template\backends\django.py", line 59, in render
    context = make_context(context, request, autoescape=self.backend.engine.autoescape)
  File "E:\项目\zhigengBlog\venv\lib\site-packages\django\template\context.py", line 268, in make_context
    raise TypeError('context must be a dict rather than %s.' % context.__class__.__name__)
TypeError: context must be a dict rather than str.
Internal Server Error: /login/
Traceback (most recent call last):
  File "E:\项目\zhigeng_Blog\Login\views.py", line 38, in login
    user = User.objects.get(name=username)
  File "E:\项目\zhigengBlog\venv\lib\site-packages\django\db\models\manager.py", line 85, in manager_method
    return getattr(self.get_queryset(), name)(*args, **kwargs)
  File "E:\项目\zhigengBlog\venv\lib\site-packages\django\db\models\query.py", line 431, in get
    self.model._meta.object_name
user.models.User.DoesNotExist: User matching query does not exist.

During handling of the above exception, another exception occurred:

Traceback (most recent call last):
  File "E:\项目\zhigengBlog\venv\lib\site-packages\django\core\handlers\exception.py", line 47, in inner
    response = get_response(request)
  File "E:\项目\zhigengBlog\venv\lib\site-packages\django\core\handlers\base.py", line 179, in _get_response
    response = wrapped_callback(request, *callback_args, **callback_kwargs)
  File "E:\项目\zhigeng_Blog\Login\views.py", line 51, in login
    return render(request, 'login.html', context)
  File "E:\项目\zhigengBlog\venv\lib\site-packages\django\shortcuts.py", line 19, in render
    content = loader.render_to_string(template_name, context, request, using=using)
  File "E:\项目\zhigengBlog\venv\lib\site-packages\django\template\loader.py", line 61, in render_to_string
    template = get_template(template_name, using=using)
  File "E:\项目\zhigengBlog\venv\lib\site-packages\django\template\loader.py", line 15, in get_template
    return engine.get_template(template_name)
  File "E:\项目\zhigengBlog\venv\lib\site-packages\django\template\backends\django.py", line 34, in get_template
    return Template(self.engine.get_template(template_name), self)
  File "E:\项目\zhigengBlog\venv\lib\site-packages\django\template\engine.py", line 143, in get_template
    template, origin = self.find_template(template_name)
  File "E:\项目\zhigengBlog\venv\lib\site-packages\django\template\engine.py", line 125, in find_template
    template = loader.get_template(name, skip=skip)
  File "E:\项目\zhigengBlog\venv\lib\site-packages\django\template\loaders\base.py", line 30, in get_template
    contents, origin, origin.template_name, self.engine,
  File "E:\项目\zhigengBlog\venv\lib\site-packages\django\template\base.py", line 155, in __init__
    self.nodelist = self.compile_nodelist()
  File "E:\项目\zhigengBlog\venv\lib\site-packages\django\template\base.py", line 193, in compile_nodelist
    return parser.parse()
  File "E:\项目\zhigengBlog\venv\lib\site-packages\django\template\base.py", line 449, in parse
    raise self.error(token, e)
  File "E:\项目\zhigengBlog\venv\lib\site-packages\django\template\base.py", line 447, in parse
    filter_expression = self.compile_filter(token.contents)
  File "E:\项目\zhigengBlog\venv\lib\site-packages\django\template\base.py", line 563, in compile_filter
    return FilterExpression(token, self)
  File "E:\项目\zhigengBlog\venv\lib\site-packages\django\template\base.py", line 663, in __init__
    "from '%s'" % (token[upto:], token))
django.template.exceptions.TemplateSyntaxError: Could not parse the remainder: '[message]' from 'context[message]'
Internal Server Error: /login/
Traceback (most recent call last):
  File "E:\项目\zhigeng_Blog\Login\views.py", line 38, in login
    user = User.objects.get(name=username)
  File "E:\项目\zhigengBlog\venv\lib\site-packages\django\db\models\manager.py", line 85, in manager_method
    return getattr(self.get_queryset(), name)(*args, **kwargs)
  File "E:\项目\zhigengBlog\venv\lib\site-packages\django\db\models\query.py", line 431, in get
    self.model._meta.object_name
user.models.User.DoesNotExist: User matching query does not exist.

During handling of the above exception, another exception occurred:

Traceback (most recent call last):
  File "E:\项目\zhigengBlog\venv\lib\site-packages\django\core\handlers\exception.py", line 47, in inner
    response = get_response(request)
  File "E:\项目\zhigengBlog\venv\lib\site-packages\django\core\handlers\base.py", line 179, in _get_response
    response = wrapped_callback(request, *callback_args, **callback_kwargs)
  File "E:\项目\zhigeng_Blog\Login\views.py", line 51, in login
    return render(request, 'login.html', context)
  File "E:\项目\zhigengBlog\venv\lib\site-packages\django\shortcuts.py", line 19, in render
    content = loader.render_to_string(template_name, context, request, using=using)
  File "E:\项目\zhigengBlog\venv\lib\site-packages\django\template\loader.py", line 61, in render_to_string
    template = get_template(template_name, using=using)
  File "E:\项目\zhigengBlog\venv\lib\site-packages\django\template\loader.py", line 15, in get_template
    return engine.get_template(template_name)
  File "E:\项目\zhigengBlog\venv\lib\site-packages\django\template\backends\django.py", line 34, in get_template
    return Template(self.engine.get_template(template_name), self)
  File "E:\项目\zhigengBlog\venv\lib\site-packages\django\template\engine.py", line 143, in get_template
    template, origin = self.find_template(template_name)
  File "E:\项目\zhigengBlog\venv\lib\site-packages\django\template\engine.py", line 125, in find_template
    template = loader.get_template(name, skip=skip)
  File "E:\项目\zhigengBlog\venv\lib\site-packages\django\template\loaders\base.py", line 30, in get_template
    contents, origin, origin.template_name, self.engine,
  File "E:\项目\zhigengBlog\venv\lib\site-packages\django\template\base.py", line 155, in __init__
    self.nodelist = self.compile_nodelist()
  File "E:\项目\zhigengBlog\venv\lib\site-packages\django\template\base.py", line 193, in compile_nodelist
    return parser.parse()
  File "E:\项目\zhigengBlog\venv\lib\site-packages\django\template\base.py", line 449, in parse
    raise self.error(token, e)
  File "E:\项目\zhigengBlog\venv\lib\site-packages\django\template\base.py", line 447, in parse
    filter_expression = self.compile_filter(token.contents)
  File "E:\项目\zhigengBlog\venv\lib\site-packages\django\template\base.py", line 563, in compile_filter
    return FilterExpression(token, self)
  File "E:\项目\zhigengBlog\venv\lib\site-packages\django\template\base.py", line 663, in __init__
    "from '%s'" % (token[upto:], token))
django.template.exceptions.TemplateSyntaxError: Could not parse the remainder: '[message]' from 'context[message]'
Internal Server Error: /register/
Traceback (most recent call last):
  File "E:\项目\zhigengBlog\venv\lib\site-packages\django\core\handlers\exception.py", line 47, in inner
    response = get_response(request)
  File "E:\项目\zhigengBlog\venv\lib\site-packages\django\core\handlers\base.py", line 186, in _get_response
    self.check_response(response, callback)
  File "E:\项目\zhigengBlog\venv\lib\site-packages\django\core\handlers\base.py", line 309, in check_response
    "instead." % name
ValueError: The view Login.views.register didn't return an HttpResponse object. It returned None instead.
Internal Server Error: /register/
Traceback (most recent call last):
  File "E:\项目\zhigengBlog\venv\lib\site-packages\django\core\handlers\exception.py", line 47, in inner
    response = get_response(request)
  File "E:\项目\zhigengBlog\venv\lib\site-packages\django\core\handlers\base.py", line 186, in _get_response
    self.check_response(response, callback)
  File "E:\项目\zhigengBlog\venv\lib\site-packages\django\core\handlers\base.py", line 309, in check_response
    "instead." % name
ValueError: The view Login.views.register didn't return an HttpResponse object. It returned None instead.
Internal Server Error: /register/
Traceback (most recent call last):
  File "E:\项目\zhigengBlog\venv\lib\site-packages\django\core\handlers\exception.py", line 47, in inner
    response = get_response(request)
  File "E:\项目\zhigengBlog\venv\lib\site-packages\django\core\handlers\base.py", line 186, in _get_response
    self.check_response(response, callback)
  File "E:\项目\zhigengBlog\venv\lib\site-packages\django\core\handlers\base.py", line 309, in check_response
    "instead." % name
ValueError: The view Login.views.register didn't return an HttpResponse object. It returned None instead.
Internal Server Error: /register/
Traceback (most recent call last):
  File "E:\项目\zhigengBlog\venv\lib\site-packages\django\core\handlers\exception.py", line 47, in inner
    response = get_response(request)
  File "E:\项目\zhigengBlog\venv\lib\site-packages\django\core\handlers\base.py", line 186, in _get_response
    self.check_response(response, callback)
  File "E:\项目\zhigengBlog\venv\lib\site-packages\django\core\handlers\base.py", line 309, in check_response
    "instead." % name
ValueError: The view Login.views.register didn't return an HttpResponse object. It returned None instead.
Internal Server Error: /register/
Traceback (most recent call last):
  File "E:\项目\zhigengBlog\venv\lib\site-packages\django\core\handlers\exception.py", line 47, in inner
    response = get_response(request)
  File "E:\项目\zhigengBlog\venv\lib\site-packages\django\core\handlers\base.py", line 186, in _get_response
    self.check_response(response, callback)
  File "E:\项目\zhigengBlog\venv\lib\site-packages\django\core\handlers\base.py", line 309, in check_response
    "instead." % name
ValueError: The view Login.views.register didn't return an HttpResponse object. It returned None instead.
Internal Server Error: /toregister/
Traceback (most recent call last):
  File "E:\项目\zhigengBlog\venv\lib\site-packages\django\core\handlers\exception.py", line 47, in inner
    response = get_response(request)
  File "E:\项目\zhigengBlog\venv\lib\site-packages\django\core\handlers\base.py", line 179, in _get_response
    response = wrapped_callback(request, *callback_args, **callback_kwargs)
  File "E:\项目\zhigeng_Blog\Login\views.py", line 52, in toregister
    return render(request, 'register/')
  File "E:\项目\zhigengBlog\venv\lib\site-packages\django\shortcuts.py", line 19, in render
    content = loader.render_to_string(template_name, context, request, using=using)
  File "E:\项目\zhigengBlog\venv\lib\site-packages\django\template\loader.py", line 61, in render_to_string
    template = get_template(template_name, using=using)
  File "E:\项目\zhigengBlog\venv\lib\site-packages\django\template\loader.py", line 19, in get_template
    raise TemplateDoesNotExist(template_name, chain=chain)
django.template.exceptions.TemplateDoesNotExist: register/
Internal Server Error: /toregister/
Traceback (most recent call last):
  File "E:\项目\zhigengBlog\venv\lib\site-packages\django\core\handlers\exception.py", line 47, in inner
    response = get_response(request)
  File "E:\项目\zhigengBlog\venv\lib\site-packages\django\core\handlers\base.py", line 179, in _get_response
    response = wrapped_callback(request, *callback_args, **callback_kwargs)
  File "E:\项目\zhigeng_Blog\Login\views.py", line 52, in toregister
    return render(request, 'register/')
  File "E:\项目\zhigengBlog\venv\lib\site-packages\django\shortcuts.py", line 19, in render
    content = loader.render_to_string(template_name, context, request, using=using)
  File "E:\项目\zhigengBlog\venv\lib\site-packages\django\template\loader.py", line 61, in render_to_string
    template = get_template(template_name, using=using)
  File "E:\项目\zhigengBlog\venv\lib\site-packages\django\template\loader.py", line 19, in get_template
    raise TemplateDoesNotExist(template_name, chain=chain)
django.template.exceptions.TemplateDoesNotExist: register/
Internal Server Error: /login/
Traceback (most recent call last):
  File "C:\Users\22520\AppData\Local\Programs\Python\Python39\lib\site-packages\django\core\handlers\exception.py", line 47, in inner
    response = get_response(request)
  File "C:\Users\22520\AppData\Local\Programs\Python\Python39\lib\site-packages\django\core\handlers\base.py", line 186, in _get_response
    self.check_response(response, callback)
  File "C:\Users\22520\AppData\Local\Programs\Python\Python39\lib\site-packages\django\core\handlers\base.py", line 307, in check_response
    raise ValueError(
ValueError: The view Login.views.login didn't return an HttpResponse object. It returned None instead.
Internal Server Error: /login/
Traceback (most recent call last):
  File "C:\Users\22520\AppData\Local\Programs\Python\Python39\lib\site-packages\django\core\handlers\exception.py", line 47, in inner
    response = get_response(request)
  File "C:\Users\22520\AppData\Local\Programs\Python\Python39\lib\site-packages\django\core\handlers\base.py", line 186, in _get_response
    self.check_response(response, callback)
  File "C:\Users\22520\AppData\Local\Programs\Python\Python39\lib\site-packages\django\core\handlers\base.py", line 307, in check_response
    raise ValueError(
ValueError: The view Login.views.login didn't return an HttpResponse object. It returned None instead.
Internal Server Error: /login/
Traceback (most recent call last):
  File "C:\Users\22520\AppData\Local\Programs\Python\Python39\lib\site-packages\django\core\handlers\exception.py", line 47, in inner
    response = get_response(request)
  File "C:\Users\22520\AppData\Local\Programs\Python\Python39\lib\site-packages\django\core\handlers\base.py", line 186, in _get_response
    self.check_response(response, callback)
  File "C:\Users\22520\AppData\Local\Programs\Python\Python39\lib\site-packages\django\core\handlers\base.py", line 307, in check_response
    raise ValueError(
ValueError: The view Login.views.login didn't return an HttpResponse object. It returned None instead.
Internal Server Error: /login/
Traceback (most recent call last):
  File "C:\Users\22520\AppData\Local\Programs\Python\Python39\lib\site-packages\django\core\handlers\exception.py", line 47, in inner
    response = get_response(request)
  File "C:\Users\22520\AppData\Local\Programs\Python\Python39\lib\site-packages\django\core\handlers\base.py", line 186, in _get_response
    self.check_response(response, callback)
  File "C:\Users\22520\AppData\Local\Programs\Python\Python39\lib\site-packages\django\core\handlers\base.py", line 307, in check_response
    raise ValueError(
ValueError: The view Login.views.login didn't return an HttpResponse object. It returned None instead.
Internal Server Error: /login/
Traceback (most recent call last):
  File "C:\Users\22520\AppData\Local\Programs\Python\Python39\lib\site-packages\django\core\handlers\exception.py", line 47, in inner
    response = get_response(request)
  File "C:\Users\22520\AppData\Local\Programs\Python\Python39\lib\site-packages\django\core\handlers\base.py", line 186, in _get_response
    self.check_response(response, callback)
  File "C:\Users\22520\AppData\Local\Programs\Python\Python39\lib\site-packages\django\core\handlers\base.py", line 307, in check_response
    raise ValueError(
ValueError: The view Login.views.login didn't return an HttpResponse object. It returned None instead.
Internal Server Error: /login/
Traceback (most recent call last):
  File "C:\Users\22520\AppData\Local\Programs\Python\Python39\lib\site-packages\django\core\handlers\exception.py", line 47, in inner
    response = get_response(request)
  File "C:\Users\22520\AppData\Local\Programs\Python\Python39\lib\site-packages\django\core\handlers\base.py", line 186, in _get_response
    self.check_response(response, callback)
  File "C:\Users\22520\AppData\Local\Programs\Python\Python39\lib\site-packages\django\core\handlers\base.py", line 307, in check_response
    raise ValueError(
ValueError: The view Login.views.login didn't return an HttpResponse object. It returned None instead.
Internal Server Error: /login/
Traceback (most recent call last):
  File "C:\Users\22520\AppData\Local\Programs\Python\Python39\lib\site-packages\django\core\handlers\exception.py", line 47, in inner
    response = get_response(request)
  File "C:\Users\22520\AppData\Local\Programs\Python\Python39\lib\site-packages\django\core\handlers\base.py", line 186, in _get_response
    self.check_response(response, callback)
  File "C:\Users\22520\AppData\Local\Programs\Python\Python39\lib\site-packages\django\core\handlers\base.py", line 307, in check_response
    raise ValueError(
ValueError: The view Login.views.login didn't return an HttpResponse object. It returned None instead.
Internal Server Error: /login/
Traceback (most recent call last):
  File "C:\Users\22520\AppData\Local\Programs\Python\Python39\lib\site-packages\django\core\handlers\exception.py", line 47, in inner
    response = get_response(request)
  File "C:\Users\22520\AppData\Local\Programs\Python\Python39\lib\site-packages\django\core\handlers\base.py", line 186, in _get_response
    self.check_response(response, callback)
  File "C:\Users\22520\AppData\Local\Programs\Python\Python39\lib\site-packages\django\core\handlers\base.py", line 307, in check_response
    raise ValueError(
ValueError: The view Login.views.login didn't return an HttpResponse object. It returned None instead.
Internal Server Error: /login/
Traceback (most recent call last):
  File "C:\Users\22520\AppData\Local\Programs\Python\Python39\lib\site-packages\django\core\handlers\exception.py", line 47, in inner
    response = get_response(request)
  File "C:\Users\22520\AppData\Local\Programs\Python\Python39\lib\site-packages\django\core\handlers\base.py", line 186, in _get_response
    self.check_response(response, callback)
  File "C:\Users\22520\AppData\Local\Programs\Python\Python39\lib\site-packages\django\core\handlers\base.py", line 307, in check_response
    raise ValueError(
ValueError: The view Login.views.login didn't return an HttpResponse object. It returned None instead.
Internal Server Error: /login/
Traceback (most recent call last):
  File "C:\Users\22520\AppData\Local\Programs\Python\Python39\lib\site-packages\django\core\handlers\exception.py", line 47, in inner
    response = get_response(request)
  File "C:\Users\22520\AppData\Local\Programs\Python\Python39\lib\site-packages\django\core\handlers\base.py", line 186, in _get_response
    self.check_response(response, callback)
  File "C:\Users\22520\AppData\Local\Programs\Python\Python39\lib\site-packages\django\core\handlers\base.py", line 307, in check_response
    raise ValueError(
ValueError: The view Login.views.login didn't return an HttpResponse object. It returned None instead.
Internal Server Error: /login/
Traceback (most recent call last):
  File "C:\Users\22520\AppData\Local\Programs\Python\Python39\lib\site-packages\django\core\handlers\exception.py", line 47, in inner
    response = get_response(request)
  File "C:\Users\22520\AppData\Local\Programs\Python\Python39\lib\site-packages\django\core\handlers\base.py", line 186, in _get_response
    self.check_response(response, callback)
  File "C:\Users\22520\AppData\Local\Programs\Python\Python39\lib\site-packages\django\core\handlers\base.py", line 307, in check_response
    raise ValueError(
ValueError: The view Login.views.login didn't return an HttpResponse object. It returned None instead.
Internal Server Error: /login/
Traceback (most recent call last):
  File "C:\Users\22520\AppData\Local\Programs\Python\Python39\lib\site-packages\django\core\handlers\exception.py", line 47, in inner
    response = get_response(request)
  File "C:\Users\22520\AppData\Local\Programs\Python\Python39\lib\site-packages\django\core\handlers\base.py", line 186, in _get_response
    self.check_response(response, callback)
  File "C:\Users\22520\AppData\Local\Programs\Python\Python39\lib\site-packages\django\core\handlers\base.py", line 307, in check_response
    raise ValueError(
ValueError: The view Login.views.login didn't return an HttpResponse object. It returned None instead.
Internal Server Error: /login/
Traceback (most recent call last):
  File "C:\Users\22520\AppData\Local\Programs\Python\Python39\lib\site-packages\django\core\handlers\exception.py", line 47, in inner
    response = get_response(request)
  File "C:\Users\22520\AppData\Local\Programs\Python\Python39\lib\site-packages\django\core\handlers\base.py", line 186, in _get_response
    self.check_response(response, callback)
  File "C:\Users\22520\AppData\Local\Programs\Python\Python39\lib\site-packages\django\core\handlers\base.py", line 307, in check_response
    raise ValueError(
ValueError: The view Login.views.login didn't return an HttpResponse object. It returned None instead.
Internal Server Error: /login/
Traceback (most recent call last):
  File "C:\Users\22520\AppData\Local\Programs\Python\Python39\lib\site-packages\django\core\handlers\exception.py", line 47, in inner
    response = get_response(request)
  File "C:\Users\22520\AppData\Local\Programs\Python\Python39\lib\site-packages\django\core\handlers\base.py", line 186, in _get_response
    self.check_response(response, callback)
  File "C:\Users\22520\AppData\Local\Programs\Python\Python39\lib\site-packages\django\core\handlers\base.py", line 307, in check_response
    raise ValueError(
ValueError: The view Login.views.login didn't return an HttpResponse object. It returned None instead.
Internal Server Error: /login/
Traceback (most recent call last):
  File "C:\Users\22520\AppData\Local\Programs\Python\Python39\lib\site-packages\django\core\handlers\exception.py", line 47, in inner
    response = get_response(request)
  File "C:\Users\22520\AppData\Local\Programs\Python\Python39\lib\site-packages\django\core\handlers\base.py", line 186, in _get_response
    self.check_response(response, callback)
  File "C:\Users\22520\AppData\Local\Programs\Python\Python39\lib\site-packages\django\core\handlers\base.py", line 307, in check_response
    raise ValueError(
ValueError: The view Login.views.login didn't return an HttpResponse object. It returned None instead.
Internal Server Error: /tosearch/
Traceback (most recent call last):
  File "E:\项目\zhigengBlog\venv\lib\site-packages\django\core\handlers\exception.py", line 47, in inner
    response = get_response(request)
  File "E:\项目\zhigengBlog\venv\lib\site-packages\django\core\handlers\base.py", line 179, in _get_response
    response = wrapped_callback(request, *callback_args, **callback_kwargs)
  File "E:\项目\zhigeng_Blog\Blog\views.py", line 16, in tosearch
    return render(request, 'search.html')
  File "E:\项目\zhigengBlog\venv\lib\site-packages\django\shortcuts.py", line 19, in render
    content = loader.render_to_string(template_name, context, request, using=using)
  File "E:\项目\zhigengBlog\venv\lib\site-packages\django\template\loader.py", line 62, in render_to_string
    return template.render(context, request)
  File "E:\项目\zhigengBlog\venv\lib\site-packages\django\template\backends\django.py", line 61, in render
    return self.template.render(context)
  File "E:\项目\zhigengBlog\venv\lib\site-packages\django\template\base.py", line 168, in render
    with context.bind_template(self):
  File "C:\Users\陈章本\AppData\Local\Programs\Python\Python37\lib\contextlib.py", line 112, in __enter__
    return next(self.gen)
  File "E:\项目\zhigengBlog\venv\lib\site-packages\django\template\context.py", line 244, in bind_template
    updates.update(processor(self.request))
  File "E:\项目\zhigengBlog\venv\lib\site-packages\django\template\context_processors.py", line 40, in debug
    if settings.DEBUG and request.META.get('REMOTE_ADDR') in settings.INTERNAL_IPS:
AttributeError: module 'django.http.request' has no attribute 'META'
